Workbook

Sheet Instructions & Glossary
B2: Sr. No | C2: Notes | I2: Sr. No | J2: Important Points & Rules for Name Change:
B3: 1 | C3: Please Enter the details only in the YELLOW boxes | F3: Sheets Name | G3: Working / Calculation in the Sheet | I3: 1 | J3: Birthday is active from 0 years to 35 years while Life Path becomes active from 36 years onwards.
B4: 2 | C4: By Entering Name, Surname & Date of Birth All Numbers get calculated automaticaly - 1. CORE - BD (Birth Date), LP (Life Path), FN (First Name), EXP (Expression No), SU (Soul Urge), SS (Secret Self), 2. Balance, Maturity, Attitude 3. Hidden Passion, 4. Karmic, 5. Challenge, 6. Pinnacles, 7. PY, PM, PD (PM & PD - For Current Full Year) 8. Please enter Gender if you are using Lo Shu Grid | F4: Master Calculator | G4: All Numbers get calculated automatically:- 1. CORE - BD (Birth Date), LP (Life Path), FN (First Name), EXP (Expression No), SU (Soul Urge), SS (Secret Self), 2. Balance, Maturity, Attitude 3. Hidden Passion, 4. Karmic, 5. Challenge, 6. Pinnacles, 7. In this seet In BD/LP Table, Whatever is Active Turns GREEN II. Name Correction - Compatibility Chart | I4: 2 | J4: Series of 4 and 8 are totally avoided in First Name and Expression Numbers while working on New spellings but can be given in Vowels and Consonants total.
B5: 3 | C5: Please DO NOT enter anything anywhere Except YELLOW BOX else the file will get corrupted | F5: Lo Shu Grid | G5: I. Pull the details from Master Calculator and Prepares Lo Shu Grid II. Pull the Name details from Master Calculator and Shows the Grid | I5: 3 | J5: If the prominent Number that is Birthday or Life Path (irrespective of what is active) is of the 3/6 series one cannot give the First Name or Expression as a 6/3 series, but it can be given in the vowels and consonants total.
B6: 4 | C6: In Karmic Numbers, KL & MKL gets highlightes with Blue Colour | F6: Current Year Personal Year-Month-Day | G6: I. Pull the Details from Master Calculator and calculates the Following 1. Current Personal Year 2. Full Years Personal Month 3. Full Years Personal Day 4. In this Personal Day gets highlighted which is compatible with BD/LP | I6: 4 | J6: The Combination of 369 is called the magical triangle in a Core.
B7: 5 | C7: In Hidden Passion the Cell will Turn Blue for the Highest Number and the rest will be Shades of Red in desending order | F7: Mobile-Vehicle-House-Bank Coompany Name | G7: 1. Calculates Mobile No. Vehicle No. House No. Bank A/c No. 2. Calculates Company Name and Compares with BD & LP | I7: 5 | J7: Avoid 4 and 9 or 8 and 9 totally in the core as these combinations attract court cases and health issues respectively.
B8: 6 | C8: In Aspect / Compatibility table E-Excellent, VG-Very Good, G-Good, F-Fair, A-Avoid & SA - Super Avoid | F8: Past - Future Personal Year-Month-Day | G8: In this Sheet one can calculate PY, PM, PD for Past and Future Year by entering DOB & Date in Yellow Box | I8: 6 | J8: If the First Name or Expression comes to a Harsh Number, it is a mandate to give a new spelling.
B9: 7 | C9: In Aspects / Compatibility table if result is A-Avoid or SA-Super Avoid the Box will turn RED | D9: A - SA | I9: 7 | J9: The following details to be taken by the client over email- Full Date of Birth; Name as in use and as on documents; Issues (if any) and Desire of the client.
B10: 8 | C10: This Sheet only calculate the numbers and does not give any corrections or predictions. You can play and do comparison with Old & New name by making changes till the Aspects / Compatibility table Turn All WHITE | I10: 8 | J10: The first step is checking the active component (Birthday or life Path as per the age). Once the active component is ascertained check it with the First Name, Expression, Soul Urge and Secret Self Number. Make use of the Aspects shared above for this purpose. Then check the First Name and Expression and see if they come to Harsh/Good/Very Good or Numbers. If they come to Harsh Numbers, then even if they get a tick in the aspects part while checking still the person would require a spelling change.
B11: 9 | C11: You will have to refer to Notes to understand the definition of Numbers and other calculations (Challenge, Pinnacles etc.) | I11: 9 | J11: The Suggested (worked) spelling to be written 21 times thrice a day (morning-afternoon-night) with a green coloured pen (ink green) for minimal 6 months in a new copy from the New Moon or Full Moon Day whichever falls earlier (time as per your choice) for a minimum of 6 months. Make sure the writing is neat and clear. It’s your choice to write in cursive handwriting or in capital letters. Failure to write the spelling won't bring any changes hence make it a daily happy ritual to write the name and write it with positivity and happiness...You are welcome to change the spelling in social networking sites, signature of your emails and in any other place where you can though no legal changes are required anywhere .. If you are not comfortable changing the spelling on social networking site, please carry on only with religiously practicing the new spelling daily and encounter bliss in the coming days...
B12: 10 | C12: For Your convenience, I have made the Alphabet table highlighting Vowels which will help on Spelling corrections | I12: 10 | J12: Once the copy in which the name is being written is finished, it can be put in the soil or can be put in a nearby lake/river/sea.
B13: 11 | C13: Apart from there is a separate sheet to calculate all the below calculations 1. Mobile, 2. Bank A/c No., 3. Vehicle, 4. House numbers
B14: 12 | C14: You can also calcuate and correct COMPANY Names, which gives result after comparing with BD & LP.

Sheet Working File
C1: D | D1: D | F1: M | G1: M | I1: Y | J1: Y | K1: Y | L1: Y | P1: 1 | Q1: 2 | R1: 3 | S1: 4 | T1: 5 | U1: 6 | V1: 7 | W1: 8 | X1: 9 | AL1: 1 | AM1: 2 | AN1: 3 | AO1: 4 | AP1: 5 | AQ1: 6 | AR1: 7 | AS1: 8
A2: Date of Birth | B2: 27896 | C2: =MID(A4,1,1) -> 1 | D2: =MID(A4,2,1) -> 6 | F2: =MID(A4,4,1) -> 0 | G2: =MID(A4,5,1) -> 5 | I2: =MID(A4,7,1) -> 1 | J2: =MID(A4,8,1) -> 9 | K2: =MID(A4,9,1) -> 7 | L2: =MID(A4,10,1) -> 6 | N2: BD | O2: =AA14 -> 7 | P2: =INDEX($AR$21:$BA$32,MATCH(P$1,$AR$21:$BA$21,0),MATCH($O$2,$AR$21:$AR$32,0)) -> G | Q2: =INDEX($AR$21:$BA$32,MATCH(Q$1,$AR$21:$BA$21,0),MATCH($O$2,$AR$21:$AR$32,0)) -> VG | R2: =INDEX($AR$21:$BA$32,MATCH(R$1,$AR$21:$BA$21,0),MATCH($O$2,$AR$21:$AR$32,0)) -> G | S2: =INDEX($AR$21:$BA$32,MATCH(S$1,$AR$21:$BA$21,0),MATCH($O$2,$AR$21:$AR$32,0)) -> G | T2: =INDEX($AR$21:$BA$32,MATCH(T$1,$AR$21:$BA$21,0),MATCH($O$2,$AR$21:$AR$32,0)) -> G | U2: =INDEX($AR$21:$BA$32,MATCH(U$1,$AR$21:$BA$21,0),MATCH($O$2,$AR$21:$AR$32,0)) -> G | V2: =INDEX($AR$21:$BA$32,MATCH(V$1,$AR$21:$BA$21,0),MATCH($O$2,$AR$21:$AR$32,0)) -> E | W2: =INDEX($AR$21:$BA$32,MATCH(W$1,$AR$21:$BA$21,0),MATCH($O$2,$AR$21:$AR$32,0)) -> A | X2: =INDEX($AR$21:$BA$32,MATCH(X$1,$AR$21:$BA$21,0),MATCH($O$2,$AR$21:$AR$32,0)) -> A | AL2: A | AM2: B | AN2: C | AO2: D | AP2: E | AQ2: U | AR2: O | AS2: F
A3: =TEXT(B2,("DD-MMM")) -> 16-May | I3: =I2&J2&K2&L2 -> 1976 | L3: =SUMPRODUCT(1*MID(I3,ROW(INDIRECT("1:"&LEN(I3))),1)) -> 23 | N3: LP | O3: =AA15 -> 8 | P3: =INDEX($AR$21:$BA$32,MATCH(P$1,$AR$21:$BA$21,0),MATCH($O$3,$AR$21:$AR$32,0)) -> F | Q3: =INDEX($AR$21:$BA$32,MATCH(Q$1,$AR$21:$BA$21,0),MATCH($O$3,$AR$21:$AR$32,0)) -> A | R3: =INDEX($AR$21:$BA$32,MATCH(R$1,$AR$21:$BA$21,0),MATCH($O$3,$AR$21:$AR$32,0)) -> G | S3: =INDEX($AR$21:$BA$32,MATCH(S$1,$AR$21:$BA$21,0),MATCH($O$3,$AR$21:$AR$32,0)) -> A | T3: =INDEX($AR$21:$BA$32,MATCH(T$1,$AR$21:$BA$21,0),MATCH($O$3,$AR$21:$AR$32,0)) -> VG | U3: =INDEX($AR$21:$BA$32,MATCH(U$1,$AR$21:$BA$21,0),MATCH($O$3,$AR$21:$AR$32,0)) -> G | V3: =INDEX($AR$21:$BA$32,MATCH(V$1,$AR$21:$BA$21,0),MATCH($O$3,$AR$21:$AR$32,0)) -> A | W3: =INDEX($AR$21:$BA$32,MATCH(W$1,$AR$21:$BA$21,0),MATCH($O$3,$AR$21:$AR$32,0)) -> E | X3: =INDEX($AR$21:$BA$32,MATCH(X$1,$AR$21:$BA$21,0),MATCH($O$3,$AR$21:$AR$32,0)) -> SA | AL3: I | AM3: K | AN3: G | AO3: M | AP3: H | AQ3: V | AR3: Z | AS3: P
A4: =TEXT(B2,"DD-MM-YYYY") -> 16-05-1976 | B4: Zodiac & Element | C4: BD | F4: BM | I4: BY | AL4: J | AM4: R | AN4: L | AO4: T | AP4: N | AQ4: W
B5: =CHOOSE(MATCH(1,(DATEVALUE({"22/12/2011","21/01/2012","20/02/2012","21/03/2012","21/04/2012","22/05/2012","22/06/2012","23/07/2012","23/08/2012","24/09/2012","24/10/2012","23/11/2012","22/12/2012"})<=DATEVALUE(TEXT(B2,"dd/mm/")&"2012"))*(DATEVALUE({"20/01/2012","19/02/2012","20/03/2012","20/04/2012","21/05/2012","21/06/2012","22/07/2012","22/08/2012","23/09/2012","23/10/2012","22/11/2012","21/12/2012","20/01/2013"})>=DATEVALUE(TEXT(B2,"dd/mm/")&"2012")),0),"Capricorn - Earth","Aquarius - Air","Pisces - Water","Aries - Fire","Taurus - Earth","Gemini - Air","Cancer - Water","Leo - Fire","Virgo - Earth","Libra - Air","Scorpio - Water","Sagittarius Fire","Capricorn - Earth") -> Taurus - Earth | C5: =C2+D2 -> 7 | F5: =F2+G2 -> 5 | I5: =SUMPRODUCT(1*MID(L3,ROW(INDIRECT("1:"&LEN(L3))),1)) -> 5 | P5: 1 | Q5: 2 | R5: 3 | S5: 4 | T5: 5 | U5: 6 | V5: 7 | W5: 8 | X5: 9 | AL5: Q | AN5: S | AP5: X
B6: BD | C6: =IF(LEN(C5)>1,LEFT(C5,1)+RIGHT(C5,1),C5) -> 7 | F6: =IF(LEN(F5)>1,LEFT(F5,1)+RIGHT(F5,1),F5) -> 5 | I6: =SUMPRODUCT(1*MID(I5,ROW(INDIRECT("1:"&LEN(I5))),1)) -> 5 | P6: 10 | Q6: 11 | R6: 12 | S6: 13 | T6: 14 | U6: 15 | V6: 16 | W6: 17 | X6: 18 | AL6: Y
B7: LP | C7: =MOD((C6+F6+I6)-1,9)+1 -> 8 | P7: 19 | Q7: 20 | R7: 21 | S7: 22 | T7: 23 | U7: 24 | V7: 25 | W7: 26 | X7: 27
P8: 28 | Q8: 29 | R8: 30 | S8: 31 | T8: 32 | U8: 33 | V8: 34 | W8: 35 | X8: 36
A9: Gender | B9: Male | D9: Age | P9: 37 | Q9: 38 | R9: 39 | S9: 40 | T9: 41 | U9: 42 | V9: 43 | W9: 44 | X9: 45
D10: =(TODAY()-B2)/365 -> 49.178082 | P10: 46 | Q10: 47 | R10: 48 | S10: 49 | T10: 50 | U10: 51 | V10: 52
AB12: Old Aspects / Compatibility | AI12: =IF(LEN(AA14)>1,LEFT(AA14,1)+RIGHT(AA14,1),AA14) -> 7 | GB12: No | GC12: Rank | GG12: Compatibility Table | GR12: Alphabet | GS12: Number | GU12: Compound Numbers | GY12: Vowels | GZ12: a | HA12: e | HB12: i | HC12: o | HD12: u | HG12: Date | HH12: Date | HI12: Zodiac | HJ12: Element | HK12: =HI12&" - "&HJ12 -> Zodiac - Element
A13: Current Name | Y13: Old Core | AB13: With BD | AC13: With LP | AI13: =IF(LEN(AA15)>1,LEFT(AA15,1)+RIGHT(AA15,1),AA15) -> 8 | GB13: 5 | GC13: G | GH13: 1 | GI13: 2 | GJ13: 3 | GK13: 4 | GL13: 5 | GM13: 6 | GN13: 7 | GO13: 8 | GP13: 9 | GR13: A | GS13: 1 | GU13: No | GV13: Rank | GZ13: 1 | HA13: 5 | HB13: 1 | HC13: 7 | HD13: 6 | HG13: 43831 | HH13: =TEXT(HG13,"DD-MMM") -> 01-Jan | HI13: Capricorn | HJ13: Earth | HK13: =HI13&" - "&HJ13 -> Capricorn - Earth
A14: First Name | B14: Mannooj | C14: =MID($B14,COLUMNS($B$13:B$13),1) -> M | D14: =MID($B14,COLUMNS($B$13:C$13),1) -> a | E14: =MID($B14,COLUMNS($B$13:D$13),1) -> n | F14: =MID($B14,COLUMNS($B$13:E$13),1) -> n | G14: =MID($B14,COLUMNS($B$13:F$13),1) -> o | H14: =MID($B14,COLUMNS($B$13:G$13),1) -> o | I14: =MID($B14,COLUMNS($B$13:H$13),1) -> j | J14: =MID($B14,COLUMNS($B$13:I$13),1) | ... T14: =MID($B14,COLUMNS($B$13:S$13),1) | Y14: BD | Z14: =C$5 -> 7 | AA14: =C6 -> 7 | AB14: =IF(D10<=35,"Active",0) -> 0 | AC14: =IF(D10>35,"Active",0) -> Active | AI14: =IF(LEN(AA16)>1,LEFT(AA16,1)+RIGHT(AA16,1),AA16) -> 3 | GB14: 6 | GC14: G | GG14: 1 | GH14: E | GI14: G | GJ14: G | GK14: F | GL14: G | GM14: F | GN14: G | GO14: F | GP14: A | GR14: B | GS14: 2 | GU14: 1 | GV14: X | HG14: 43832 | HH14: =TEXT(HG14,"DD-MMM") -> 02-Jan | HI14: Capricorn | HJ14: Earth | HK14: =HI14&" - "&HJ14 -> Capricorn - Earth
C15: =IFERROR(VLOOKUP(C14,GR:GS,2,0),0) -> 4 | D15: =IFERROR(VLOOKUP(D14,GR:GS,2,0),0) -> 1 | E15: =IFERROR(VLOOKUP(E14,GR:GS,2,0),0) -> 5 | F15: =IFERROR(VLOOKUP(F14,GR:GS,2,0),0) -> 5 | G15: =IFERROR(VLOOKUP(G14,GR:GS,2,0),0) -> 7 | H15: =IFERROR(VLOOKUP(H14,GR:GS,2,0),0) -> 7 | I15: =IFERROR(VLOOKUP(I14,GR:GS,2,0),0) -> 1 | J15: =IFERROR(VLOOKUP(J14,GR:GS,2,0),0) -> 0 | ... T15: =IFERROR(VLOOKUP(T14,GR:GS,2,0),0) -> 0 | U15: =SUM(C15:T15) -> 30 | V15: =IF(U15<10,U15,((LEFT(U15,1))+(RIGHT(U15,1)))) -> 3 | W15: FN | X15: =IF(U15>52,VLOOKUP(V15,GU:GV,2,0),VLOOKUP(U15,GU:GV,2,0)) -> * | Y15: LP | Z15: =I$5+F$5+C$5 -> 17 | AA15: =C7 -> 8 | AI15: =IF(LEN(AA17)>1,LEFT(AA17,1)+RIGHT(AA17,1),AA17) -> 5 | GB15: 10 | GC15: G | GG15: 2 | GH15: G | GI15: E | GJ15: G | GK15: G | GL15: F | GM15: G | GN15: VG | GO15: A | GP15: A | GR15: C | GS15: 3 | GU15: 2 | GV15: X | GX15: FN Vowel | GY15: =(GZ15*GZ16)+(HA15*HA16)+(HB15*HB16)+(HC15*HC16)+(HD15*HD16) -> 15 | GZ15: =IFERROR((HLOOKUP(GZ12,C14:T15,2,0)),0) -> 1 | HA15: =IFERROR((HLOOKUP(HA12,C14:T15,2,0)),0) -> 0 | HB15: =IFERROR((HLOOKUP(HB12,C14:T15,2,0)),0) -> 0 | HC15: =IFERROR((HLOOKUP(HC12,C14:T15,2,0)),0) -> 7 | HD15: =IFERROR((HLOOKUP(HD12,C14:T15,2,0)),0) -> 0 | HG15: 43833 | HH15: =TEXT(HG15,"DD-MMM") -> 03-Jan | HI15: Capricorn | HJ15: Earth | HK15: =HI15&" - "&HJ15 -> Capricorn - Earth
A16: Middle Name | C16: =MID($B16,COLUMNS($B$15:B$15),1) | D16: =MID($B16,COLUMNS($B$15:C$15),1) | E16: =MID($B16,COLUMNS($B$15:D$15),1) | F16: =MID($B16,COLUMNS($B$15:E$15),1) | G16: =MID($B16,COLUMNS($B$15:F$15),1) | H16: =MID($B16,COLUMNS($B$15:G$15),1) | I16: =MID($B16,COLUMNS($B$15:H$15),1) | J16: =MID($B16,COLUMNS($B$15:I$15),1) | ... T16: =MID($B16,COLUMNS($B$15:S$15),1) | Y16: FN | Z16: =U15 -> 30 | AA16: =MOD(Z16-1,9)+1 -> 3 | AB16: =INDEX(GH$14:GP$22,MATCH(IF(LEN(AA$14)>1,LEFT(AA$14,1)+RIGHT(AA$14,1),AA$14),GG$14:GG$22,0),MATCH(IF(LEN(AA16)>1,LEFT(AA16,1)+RIGHT(AA16,1),AA16),GH$13:GP$13,0)) -> G | AC16: =INDEX(GH$14:GP$22,MATCH(IF(LEN(AA$15)>1,LEFT(AA$15,1)+RIGHT(AA$15,1),AA$15),GG$14:GG$22,0),MATCH(IF(LEN(AA16)>1,LEFT(AA16,1)+RIGHT(AA16,1),AA16),GH$13:GP$13,0)) -> G | AI16: =IF(LEN(AA18)>1,LEFT(AA18,1)+RIGHT(AA18,1),AA18) -> 6 | GB16: 12 | GC16: G | GG16: 3 | GH16: G | GI16: G | GJ16: E | GK16: A | GL16: G | GM16: A | GN16: G | GO16: G | GP16: G | GR16: D | GS16: 4 | GU16: 3 | GV16: X | GZ16: =COUNTIFS(C14:T14,GZ12) -> 1 | HA16: =COUNTIFS(C14:T14,HA12) -> 0 | HB16: =COUNTIFS(C14:T14,HB12) -> 0 | HC16: =COUNTIFS(C14:T14,HC12) -> 2 | HD16: =COUNTIFS(C14:T14,HD12) -> 0 | HG16: 43834 | HH16: =TEXT(HG16,"DD-MMM") -> 04-Jan | HI16: Capricorn | HJ16: Earth | HK16: =HI16&" - "&HJ16 -> Capricorn - Earth
C17: =IFERROR(VLOOKUP(C16,GR:GS,2,0),0) -> 0 | D17: =IFERROR(VLOOKUP(D16,GR:GS,2,0),0) -> 0 | E17: =IFERROR(VLOOKUP(E16,GR:GS,2,0),0) -> 0 | F17: =IFERROR(VLOOKUP(F16,GR:GS,2,0),0) -> 0 | G17: =IFERROR(VLOOKUP(G16,GR:GS,2,0),0) -> 0 | H17: =IFERROR(VLOOKUP(H16,GR:GS,2,0),0) -> 0 | I17: =IFERROR(VLOOKUP(I16,GR:GS,2,0),0) -> 0 | J17: =IFERROR(VLOOKUP(J16,GR:GS,2,0),0) -> 0 | ... T17: =IFERROR(VLOOKUP(T16,GR:GS,2,0),0) -> 0 | U17: =SUM(C17:T17) -> 0 | V17: =IF(U17<10,U17,((LEFT(U17,1))+(RIGHT(U17,1)))) -> 0 | Y17: EXP | Z17: =U20 -> 50 | AA17: =MOD(Z17-1,9)+1 -> 5 | AB17: =INDEX(GH$14:GP$22,MATCH(IF(LEN(AA$14)>1,LEFT(AA$14,1)+RIGHT(AA$14,1),AA$14),GG$14:GG$22,0),MATCH(IF(LEN(AA17)>1,LEFT(AA17,1)+RIGHT(AA17,1),AA17),GH$13:GP$13,0)) -> G | AC17: =INDEX(GH$14:GP$22,MATCH(IF(LEN(AA$15)>1,LEFT(AA$15,1)+RIGHT(AA$15,1),AA$15),GG$14:GG$22,0),MATCH(IF(LEN(AA17)>1,LEFT(AA17,1)+RIGHT(AA17,1),AA17),GH$13:GP$13,0)) -> VG | AI17: =IF(LEN(AA19)>1,LEFT(AA19,1)+RIGHT(AA19,1),AA19) -> 8 | GB17: 13 | GC17: G | GG17: 4 | GH17: F | GI17: G | GJ17: A | GK17: E | GL17: G | GM17: G | GN17: G | GO17: A | GP17: SA | GR17: E | GS17: 5 | GU17: 4 | GV17: X | HG17: 43835 | HH17: =TEXT(HG17,"DD-MMM") -> 05-Jan | HI17: Capricorn | HJ17: Earth | HK17: =HI17&" - "&HJ17 -> Capricorn - Earth
A18: Last Name | B18: Kasturia | C18: =MID($B18,COLUMNS($B$15:B$15),1) -> K | D18: =MID($B18,COLUMNS($B$15:C$15),1) -> a | E18: =MID($B18,COLUMNS($B$15:D$15),1) -> s | F18: =MID($B18,COLUMNS($B$15:E$15),1) -> t | G18: =MID($B18,COLUMNS($B$15:F$15),1) -> u | H18: =MID($B18,COLUMNS($B$15:G$15),1) -> r | I18: =MID($B18,COLUMNS($B$15:H$15),1) -> i | J18: =MID($B18,COLUMNS($B$15:I$15),1) -> a | ... T18: =MID($B18,COLUMNS($B$15:S$15),1) | Y18: SU | Z18: =GY15+GY21+GY18 -> 24 | AA18: =MOD(Z18-1,9)+1 -> 6 | AB18: =INDEX(GH$14:GP$22,MATCH(IF(LEN(AA$14)>1,LEFT(AA$14,1)+RIGHT(AA$14,1),AA$14),GG$14:GG$22,0),MATCH(IF(LEN(AA18)>1,LEFT(AA18,1)+RIGHT(AA18,1),AA18),GH$13:GP$13,0)) -> G | AC18: =INDEX(GH$14:GP$22,MATCH(IF(LEN(AA$15)>1,LEFT(AA$15,1)+RIGHT(AA$15,1),AA$15),GG$14:GG$22,0),MATCH(IF(LEN(AA18)>1,LEFT(AA18,1)+RIGHT(AA18,1),AA18),GH$13:GP$13,0)) -> G | GB18: 14 | GC18: G | GG18: 5 | GH18: G | GI18: F | GJ18: G | GK18: G | GL18: E | GM18: F | GN18: G | GO18: VG | GP18: F | GR18: F | GS18: 8 | GU18: 5 | GV18: √ | GX18: MN Vovel | GY18: =(GZ18*GZ19)+(HA18*HA19)+(HB18*HB19)+(HC18*HC19)+(HD18*HD19) -> 0 | GZ18: =IFERROR((HLOOKUP(GZ12,C16:T17,2,0)),0) -> 0 | HA18: =IFERROR((HLOOKUP(HA12,C16:T17,2,0)),0) -> 0 | HB18: =IFERROR((HLOOKUP(HB12,C16:T17,2,0)),0) -> 0 | HC18: =IFERROR((HLOOKUP(HC12,C16:T17,2,0)),0) -> 0 | HD18: =IFERROR((HLOOKUP(HD12,C16:T17,2,0)),0) -> 0 | HG18: 43836 | HH18: =TEXT(HG18,"DD-MMM") -> 06-Jan | HI18: Capricorn | HJ18: Earth | HK18: =HI18&" - "&HJ18 -> Capricorn - Earth
C19: =IFERROR(VLOOKUP(C18,GR:GS,2,0),0) -> 2 | D19: =IFERROR(VLOOKUP(D18,GR:GS,2,0),0) -> 1 | E19: =IFERROR(VLOOKUP(E18,GR:GS,2,0),0) -> 3 | F19: =IFERROR(VLOOKUP(F18,GR:GS,2,0),0) -> 4 | G19: =IFERROR(VLOOKUP(G18,GR:GS,2,0),0) -> 6 | H19: =IFERROR(VLOOKUP(H18,GR:GS,2,0),0) -> 2 | I19: =IFERROR(VLOOKUP(I18,GR:GS,2,0),0) -> 1 | J19: =IFERROR(VLOOKUP(J18,GR:GS,2,0),0) -> 1 | ... T19: =IFERROR(VLOOKUP(T18,GR:GS,2,0),0) -> 0 | U19: =SUM(C19:T19) -> 20 | V19: =IF(U19<10,U19,((LEFT(U19,1))+(RIGHT(U19,1)))) -> 2 | Y19: SS | Z19: =Z17-Z18 -> 26 | AA19: =MOD(Z19-1,9)+1 -> 8 | AB19: =INDEX(GH$14:GP$22,MATCH(IF(LEN(AA$14)>1,LEFT(AA$14,1)+RIGHT(AA$14,1),AA$14),GG$14:GG$22,0),MATCH(IF(LEN(AA19)>1,LEFT(AA19,1)+RIGHT(AA19,1),AA19),GH$13:GP$13,0)) -> A | AC19: =INDEX(GH$14:GP$22,MATCH(IF(LEN(AA$15)>1,LEFT(AA$15,1)+RIGHT(AA$15,1),AA$15),GG$14:GG$22,0),MATCH(IF(LEN(AA19)>1,LEFT(AA19,1)+RIGHT(AA19,1),AA19),GH$13:GP$13,0)) -> E | AE19: Karmic Number | GB19: 15 | GC19: G | GG19: 6 | GH19: F | GI19: G | GJ19: A | GK19: G | GL19: F | GM19: E | GN19: G | GO19: G | GP19: G | GR19: G | GS19: 3 | GU19: 6 | GV19: √ | GZ19: =COUNTIFS(C16:T16,GZ12) -> 0 | HA19: =COUNTIFS(C16:T16,HA12) -> 0 | HB19: =COUNTIFS(C16:T16,HB12) -> 0 | HC19: =COUNTIFS(C16:T16,HC12) -> 0 | HD19: =COUNTIFS(C16:T16,HD12) -> 0 | HG19: 43837 | HH19: =TEXT(HG19,"DD-MMM") -> 07-Jan | HI19: Capricorn | HJ19: Earth | HK19: =HI19&" - "&HJ19 -> Capricorn - Earth
J20: BD | K20: LP | L20: BD | M20: LP | U20: =U19+U17+U15 -> 50 | V20: =V15+V17+V19 -> 5 | W20: EXP | X20: =IF(U20>52,VLOOKUP(V20,GU:GV,2,0),VLOOKUP(U20,GU:GV,2,0)) -> * | AB20: Hidden Passion | AE20: FN | AF20: MN | AG20: LN | AH20: Core | AI20: N | AJ20: C | AK20: KLs | AL20: MKLs | AR20: Compatibility Table | GB20: 17 | GC20: G | GG20: 7 | GH20: G | GI20: VG | GJ20: G | GK20: A | GL20: G | GM20: G | GN20: E | GO20: A | GP20: A | GR20: H | GS20: 5 | GU20: 7 | GV20: X | HG20: 43838 | HH20: =TEXT(HG20,"DD-MMM") -> 08-Jan | HI20: Capricorn | HJ20: Earth | HK20: =HI20&" - "&HJ20 -> Capricorn - Earth
D21: FN | E21: EXP | G21: FN | H21: EXP | J21: =C6 -> 7 | K21: =C7 -> 8 | L21: =C6 -> 7 | M21: =C7 -> 8 | Y21: Balance | Z21: =C15+C19 -> 6 | AA21: =IF(LEN(Z21)>1,LEFT(Z21,1)+RIGHT(Z21,1),Z21) -> 6 | AB21: 1 | AC21: =COUNTIF(C$15:T$15,AB21)+COUNTIF(C$17:T$17,AB21)+COUNTIF(C$19:T$19,AB21) -> 5 | AE21: =IFERROR(HLOOKUP(AB21,C15:T15,1,0),0) -> 1 | AF21: =IFERROR(HLOOKUP(AB21,C17:T17,1,0),0) -> 0 | AG21: =IFERROR(HLOOKUP(AB21,C19:T19,1,0),0) -> 1 | AH21: =IFERROR(VLOOKUP(AB21,AI12:AI17,1,0),0) -> 0 | AI21: =IF(SUM(AE21:AG21)>=AB21,AB21,0) -> 1 | AJ21: =IF(AH21=AB21,AB21,0) -> 0 | AK21: =IF(SUM(AI21:AJ21)<=0,AB21,0) -> 0 | AL21: =IF(AI21=AB21,0,AJ21) -> 0 | AS21: 1 | AT21: 2 | AU21: 3 | AV21: 4 | AW21: 5 | AX21: 6 | AY21: 7 | AZ21: 8 | BA21: 9 | GB21: 19 | GC21: S | GG21: 8 | GH21: F | GI21: A | GJ21: G | GK21: A | GL21: VG | GM21: G | GN21: A | GO21: E | GP21: SA | GR21: I | GS21: 1 | GU21: 8 | GV21: X | GX21: LN Vowel | GY21: =(GZ21*GZ22)+(HA21*HA22)+(HB21*HB22)+(HC21*HC22)+(HD21*HD22) -> 9 | GZ21: =IFERROR((HLOOKUP(GZ12,C18:T19,2,0)),0) -> 1 | HA21: =IFERROR((HLOOKUP(HA12,C18:T19,2,0)),0) -> 0 | HB21: =IFERROR((HLOOKUP(HB12,C18:T19,2,0)),0) -> 1 | HC21: =IFERROR((HLOOKUP(HC12,C18:T19,2,0)),0) -> 0 | HD21: =IFERROR((HLOOKUP(HD12,C18:T19,2,0)),0) -> 6 | HG21: 43839 | HH21: =TEXT(HG21,"DD-MMM") -> 09-Jan | HI21: Capricorn | HJ21: Earth | HK21: =HI21&" - "&HJ21 -> Capricorn - Earth
D22: =U15 -> 30 | E22: =U20 -> 50 | J22: FN | L22: EXP | Y22: Maturity | Z22: =AA15+AA17 -> 13 | AA22: =IF(LEN(Z22)>1,LEFT(Z22,1)+RIGHT(Z22,1),Z22) -> 4 | AB22: 2 | AC22: =COUNTIF(C$15:T$15,AB22)+COUNTIF(C$17:T$17,AB22)+COUNTIF(C$19:T$19,AB22) -> 2 | AE22: =IFERROR(HLOOKUP(AB22,C15:T15,1,0),0) -> 0 | AF22: =IFERROR(HLOOKUP(AB22,C17:T17,1,0),0) -> 0 | AG22: =IFERROR(HLOOKUP(AB22,C19:T19,1,0),0) -> 2 | AH22: =IFERROR(VLOOKUP(AB22,AI12:AI17,1,0),0) -> 0 | AI22: =IF(SUM(AE22:AG22)>=AB22,AB22,0) -> 2 | AJ22: =IF(AH22=AB22,AB22,0) -> 0 | AK22: =IF(SUM(AI22:AJ22)<=0,AB22,0) -> 0 | AL22: =IF(AI22=AB22,0,AJ22) -> 0 | AR22: 1 | AS22: E | AT22: G | AU22: G | AV22: F | AW22: G | AX22: F | AY22: G | AZ22: F | BA22: A | GB22: 20 | GC22: G | GG22: 9 | GH22: A | GI22: A | GJ22: G | GK22: A | GL22: F | GM22: G | GN22: A | GO22: A | GP22: E | GR22: J | GS22: 1 | GU22: 9 | GV22: X | GZ22: =COUNTIFS(C18:T18,GZ12) -> 2 | HA22: =COUNTIFS(C18:T18,HA12) -> 0 | HB22: =COUNTIFS(C18:T18,HB12) -> 1 | HC22: =COUNTIFS(C18:T18,HC12) -> 0 | HD22: =COUNTIFS(C18:T18,HD12) -> 1 | HG22: 43840 | HH22: =TEXT(HG22,"DD-MMM") -> 10-Jan | HI22: Capricorn | HJ22: Earth | HK22: =HI22&" - "&HJ22 -> Capricorn - Earth
C23: 1 | D23: =IF(ISERROR(INDEX(GB:GB,MATCH(D22,$GB$1:$GB$100,1)+1,1)),"",INDEX(GB:GB,MATCH(D22,$GB$1:$GB$100,1)+1,1)) -> 32 | E23: =IF(ISERROR(INDEX(GB:GB,MATCH(E22,$GB$1:$GB$100,1)+1,1)),"",INDEX(GB:GB,MATCH(E22,$GB$1:$GB$100,1)+1,1)) -> 51 | G23: =MOD(D23-1,9)+1 -> 5 | H23: =MOD(E23-1,9)+1 -> 6 | J23: =INDEX($AR$21:$BA$32,MATCH($G23,$AR$21:$BA$21,0),MATCH($J$21,$AR$21:$AR$32,0)) -> G | K23: =INDEX($AR$21:$BA$32,MATCH($G23,$AR$21:$BA$21,0),MATCH($K$21,$AR$21:$AR$32,0)) -> VG | L23: =INDEX($AR$21:$BA$32,MATCH($H23,$AR$21:$BA$21,0),MATCH($L$21,$AR$21:$AR$32,0)) -> G | M23: =INDEX($AR$21:$BA$32,MATCH($H23,$AR$21:$BA$21,0),MATCH($M$21,$AR$21:$AR$32,0)) -> G | Y23: Attitude | Z23: =C5+F5 -> 12 | AA23: =IF(LEN(Z23)>1,LEFT(Z23,1)+RIGHT(Z23,1),Z23) -> 3 | AB23: 3 | AC23: =COUNTIF(C$15:T$15,AB23)+COUNTIF(C$17:T$17,AB23)+COUNTIF(C$19:T$19,AB23) -> 1 | AE23: =IFERROR(HLOOKUP(AB23,C15:T15,1,0),0) -> 0 | AF23: =IFERROR(HLOOKUP(AB23,C17:T17,1,0),0) -> 0 | AG23: =IFERROR(HLOOKUP(AB23,C19:T19,1,0),0) -> 3 | AH23: =IFERROR(VLOOKUP(AB23,AI12:AI17,1,0),0) -> 3 | AI23: =IF(SUM(AE23:AG23)>=AB23,AB23,0) -> 3 | AJ23: =IF(AH23=AB23,AB23,0) -> 3 | AK23: =IF(SUM(AI23:AJ23)<=0,AB23,0) -> 0 | AL23: =IF(AI23=AB23,0,AJ23) -> 0 | AR23: 2 | AS23: G | AT23: E | AU23: G | AV23: G | AW23: F | AX23: G | AY23: VG | AZ23: A | BA23: A | GB23: 21 | GC23: S | GR23: K | GS23: 2 | GU23: 10 | GV23: √ | HG23: 43841 | HH23: =TEXT(HG23,"DD-MMM") -> 11-Jan | HI23: Capricorn | HJ23: Earth | HK23: =HI23&" - "&HJ23 -> Capricorn - Earth
C24: 2 | D24: =IF(ISERROR(INDEX(GB:GB,MATCH(D23,$GB$1:$GB$33,1)+1,1)),"",INDEX(GB:GB,MATCH(D23,$GB$1:$GB$33,1)+1,1)) -> 33 | E24: =IF(ISERROR(INDEX(GB:GB,MATCH(E23,$GB$1:$GB$100,1)+1,1)),"",INDEX(GB:GB,MATCH(E23,$GB$1:$GB$100,1)+1,1)) -> 52 | G24: =MOD(D24-1,9)+1 -> 6 | H24: =MOD(E24-1,9)+1 -> 7 | J24: =INDEX($AR$21:$BA$32,MATCH($G24,$AR$21:$BA$21,0),MATCH($J$21,$AR$21:$AR$32,0)) -> G | K24: =INDEX($AR$21:$BA$32,MATCH($G24,$AR$21:$BA$21,0),MATCH($K$21,$AR$21:$AR$32,0)) -> G | L24: =INDEX($AR$21:$BA$32,MATCH($H24,$AR$21:$BA$21,0),MATCH($L$21,$AR$21:$AR$32,0)) -> E | M24: =INDEX($AR$21:$BA$32,MATCH($H24,$AR$21:$BA$21,0),MATCH($M$21,$AR$21:$AR$32,0)) -> A | AB24: 4 | AC24: =COUNTIF(C$15:T$15,AB24)+COUNTIF(C$17:T$17,AB24)+COUNTIF(C$19:T$19,AB24) -> 2 | AE24: =IFERROR(HLOOKUP(AB24,C15:T15,1,0),0) -> 4 | AF24: =IFERROR(HLOOKUP(AB24,C17:T17,1,0),0) -> 0 | AG24: =IFERROR(HLOOKUP(AB24,C19:T19,1,0),0) -> 4 | AH24: =IFERROR(VLOOKUP(AB24,AI12:AI17,1,0),0) -> 0 | AI24: =IF(SUM(AE24:AG24)>=AB24,AB24,0) -> 4 | AJ24: =IF(AH24=AB24,AB24,0) -> 0 | AK24: =IF(SUM(AI24:AJ24)<=0,AB24,0) -> 0 | AL24: =IF(AI24=AB24,0,AJ24) -> 0 | AR24: 3 | AS24: G | AT24: G | AU24: E | AV24: A | AW24: G | AX24: A | AY24: G | AZ24: G | BA24: G | GB24: 23 | GC24: S | GH24: A | GI24: B | GJ24: C | GK24: D | GL24: E | GM24: U | GN24: O | GO24: F | GR24: L | GS24: 3 | GU24: 11 | GV24: X | HG24: 43842 | HH24: =TEXT(HG24,"DD-MMM") -> 12-Jan | HI24: Capricorn | HJ24: Earth | HK24: =HI24&" - "&HJ24 -> Capricorn - Earth
C25: 3 | D25: =IF(ISERROR(INDEX(GB:GB,MATCH(D24,$GB$1:$GB$33,1)+1,1)),"",INDEX(GB:GB,MATCH(D24,$GB$1:$GB$33,1)+1,1)) -> 34 | E25: =IF(ISERROR(INDEX(GB:GB,MATCH(E24,$GB$1:$GB$100,1)+1,1)),"",INDEX(GB:GB,MATCH(E24,$GB$1:$GB$100,1)+1,1)) -> 55 | G25: =MOD(D25-1,9)+1 -> 7 | H25: =MOD(E25-1,9)+1 -> 1 | J25: =INDEX($AR$21:$BA$32,MATCH($G25,$AR$21:$BA$21,0),MATCH($J$21,$AR$21:$AR$32,0)) -> E | K25: =INDEX($AR$21:$BA$32,MATCH($G25,$AR$21:$BA$21,0),MATCH($K$21,$AR$21:$AR$32,0)) -> A | L25: =INDEX($AR$21:$BA$32,MATCH($H25,$AR$21:$BA$21,0),MATCH($L$21,$AR$21:$AR$32,0)) -> G | M25: =INDEX($AR$21:$BA$32,MATCH($H25,$AR$21:$BA$21,0),MATCH($M$21,$AR$21:$AR$32,0)) -> F | AB25: 5 | AC25: =COUNTIF(C$15:T$15,AB25)+COUNTIF(C$17:T$17,AB25)+COUNTIF(C$19:T$19,AB25) -> 2 | AE25: =IFERROR(HLOOKUP(AB25,C15:T15,1,0),0) -> 5 | AF25: =IFERROR(HLOOKUP(AB25,C17:T17,1,0),0) -> 0 | AG25: =IFERROR(HLOOKUP(AB25,C19:T19,1,0),0) -> 0 | AH25: =IFERROR(VLOOKUP(AB25,AI12:AI17,1,0),0) -> 5 | AI25: =IF(SUM(AE25:AG25)>=AB25,AB25,0) -> 5 | AJ25: =IF(AH25=AB25,AB25,0) -> 5 | AK25: =IF(SUM(AI25:AJ25)<=0,AB25,0) -> 0 | AL25: =IF(AI25=AB25,0,AJ25) -> 0 | AR25: 4 | AS25: F | AT25: G | AU25: A | AV25: E | AW25: G | AX25: G | AY25: G | AZ25: A | BA25: SA | GB25: 24 | GC25: S | GH25: I | GI25: K | GJ25: G | GK25: M | GL25: H | GM25: V | GN25: Z | GO25: P | GR25: M | GS25: 4 | GU25: 12 | GV25: √ | HG25: 43843 | HH25: =TEXT(HG25,"DD-MMM") -> 13-Jan | HI25: Capricorn | HJ25: Earth | HK25: =HI25&" - "&HJ25 -> Capricorn - Earth
C26: 4 | D26: =IF(ISERROR(INDEX(GB:GB,MATCH(D25,$GB$1:$GB$33,1)+1,1)),"",INDEX(GB:GB,MATCH(D25,$GB$1:$GB$33,1)+1,1)) -> 36 | E26: =IF(ISERROR(INDEX(GB:GB,MATCH(E25,$GB$1:$GB$100,1)+1,1)),"",INDEX(GB:GB,MATCH(E25,$GB$1:$GB$100,1)+1,1)) -> 57 | G26: =MOD(D26-1,9)+1 -> 9 | H26: =MOD(E26-1,9)+1 -> 3 | J26: =INDEX($AR$21:$BA$32,MATCH($G26,$AR$21:$BA$21,0),MATCH($J$21,$AR$21:$AR$32,0)) -> A | K26: =INDEX($AR$21:$BA$32,MATCH($G26,$AR$21:$BA$21,0),MATCH($K$21,$AR$21:$AR$32,0)) -> SA | L26: =INDEX($AR$21:$BA$32,MATCH($H26,$AR$21:$BA$21,0),MATCH($L$21,$AR$21:$AR$32,0)) -> G | M26: =INDEX($AR$21:$BA$32,MATCH($H26,$AR$21:$BA$21,0),MATCH($M$21,$AR$21:$AR$32,0)) -> G | AB26: 6 | AC26: =COUNTIF(C$15:T$15,AB26)+COUNTIF(C$17:T$17,AB26)+COUNTIF(C$19:T$19,AB26) -> 1 | AE26: =IFERROR(HLOOKUP(AB26,C15:T15,1,0),0) -> 0 | AF26: =IFERROR(HLOOKUP(AB26,C17:T17,1,0),0) -> 0 | AG26: =IFERROR(HLOOKUP(AB26,C19:T19,1,0),0) -> 6 | AH26: =IFERROR(VLOOKUP(AB26,AI12:AI17,1,0),0) -> 6 | AI26: =IF(SUM(AE26:AG26)>=AB26,AB26,0) -> 6 | AJ26: =IF(AH26=AB26,AB26,0) -> 6 | AK26: =IF(SUM(AI26:AJ26)<=0,AB26,0) -> 0 | AL26: =IF(AI26=AB26,0,AJ26) -> 0 | AR26: 5 | AS26: G | AT26: F | AU26: G | AV26: G | AW26: E | AX26: F | AY26: G | AZ26: VG | BA26: F | GB26: 25 | GC26: G | GH26: J | GI26: R | GJ26: L | GK26: T | GL26: N | GM26: W | GR26: N | GS26: 5 | GU26: 13 | GV26: √ | HG26: 43844 | HH26: =TEXT(HG26,"DD-MMM") -> 14-Jan | HI26: Capricorn | HJ26: Earth | HK26: =HI26&" - "&HJ26 -> Capricorn - Earth
C27: 5 | D27: =IF(ISERROR(INDEX(GB:GB,MATCH(D26,$GB$1:$GB$33,1)+1,1)),"",INDEX(GB:GB,MATCH(D26,$GB$1:$GB$33,1)+1,1)) -> 37 | E27: =IF(ISERROR(INDEX(GB:GB,MATCH(E26,$GB$1:$GB$100,1)+1,1)),"",INDEX(GB:GB,MATCH(E26,$GB$1:$GB$100,1)+1,1)) -> 59 | G27: =MOD(D27-1,9)+1 -> 1 | H27: =MOD(E27-1,9)+1 -> 5 | J27: =INDEX($AR$21:$BA$32,MATCH($G27,$AR$21:$BA$21,0),MATCH($J$21,$AR$21:$AR$32,0)) -> G | K27: =INDEX($AR$21:$BA$32,MATCH($G27,$AR$21:$BA$21,0),MATCH($K$21,$AR$21:$AR$32,0)) -> F | L27: =INDEX($AR$21:$BA$32,MATCH($H27,$AR$21:$BA$21,0),MATCH($L$21,$AR$21:$AR$32,0)) -> G | M27: =INDEX($AR$21:$BA$32,MATCH($H27,$AR$21:$BA$21,0),MATCH($M$21,$AR$21:$AR$32,0)) -> VG | AB27: 7 | AC27: =COUNTIF(C$15:T$15,AB27)+COUNTIF(C$17:T$17,AB27)+COUNTIF(C$19:T$19,AB27) -> 2 | AE27: =IFERROR(HLOOKUP(AB27,C15:T15,1,0),0) -> 7 | AF27: =IFERROR(HLOOKUP(AB27,C17:T17,1,0),0) -> 0 | AG27: =IFERROR(HLOOKUP(AB27,C19:T19,1,0),0) -> 0 | AH27: =IFERROR(VLOOKUP(AB27,AI12:AI17,1,0),0) -> 7 | AI27: =IF(SUM(AE27:AG27)>=AB27,AB27,0) -> 7 | AJ27: =IF(AH27=AB27,AB27,0) -> 7 | AK27: =IF(SUM(AI27:AJ27)<=0,AB27,0) -> 0 | AL27: =IF(AI27=AB27,0,AJ27) -> 0 | AR27: 6 | AS27: F | AT27: G | AU27: A | AV27: G | AW27: F | AX27: E | AY27: G | AZ27: G | BA27: G | BF27: BD | BG27: LP | GB27: 27 | GC27: G | GH27: Q | GJ27: S | GL27: X | GR27: O | GS27: 7 | GU27: 14 | GV27: √ | HG27: 43845 | HH27: =TEXT(HG27,"DD-MMM") -> 15-Jan | HI27: Capricorn | HJ27: Earth | HK27: =HI27&" - "&HJ27 -> Capricorn - Earth
C28: 6 | D28: =IF(ISERROR(INDEX(GB:GB,MATCH(D27,$GB$1:$GB$33,1)+1,1)),"",INDEX(GB:GB,MATCH(D27,$GB$1:$GB$33,1)+1,1)) -> 38 | E28: =IF(ISERROR(INDEX(GB:GB,MATCH(E27,$GB$1:$GB$100,1)+1,1)),"",INDEX(GB:GB,MATCH(E27,$GB$1:$GB$100,1)+1,1)) -> 60 | G28: =MOD(D28-1,9)+1 -> 2 | H28: =MOD(E28-1,9)+1 -> 6 | J28: =INDEX($AR$21:$BA$32,MATCH($G28,$AR$21:$BA$21,0),MATCH($J$21,$AR$21:$AR$32,0)) -> VG | K28: =INDEX($AR$21:$BA$32,MATCH($G28,$AR$21:$BA$21,0),MATCH($K$21,$AR$21:$AR$32,0)) -> A | L28: =INDEX($AR$21:$BA$32,MATCH($H28,$AR$21:$BA$21,0),MATCH($L$21,$AR$21:$AR$32,0)) -> G | M28: =INDEX($AR$21:$BA$32,MATCH($H28,$AR$21:$BA$21,0),MATCH($M$21,$AR$21:$AR$32,0)) -> G | AB28: 8 | AC28: =COUNTIF(C$15:T$15,AB28)+COUNTIF(C$17:T$17,AB28)+COUNTIF(C$19:T$19,AB28) -> 0 | AE28: =IFERROR(HLOOKUP(AB28,C15:T15,1,0),0) -> 0 | AF28: =IFERROR(HLOOKUP(AB28,C17:T17,1,0),0) -> 0 | AG28: =IFERROR(HLOOKUP(AB28,C19:T19,1,0),0) -> 0 | AH28: =IFERROR(VLOOKUP(AB28,AI12:AI17,1,0),0) -> 8 | AI28: =IF(SUM(AE28:AG28)>=AB28,AB28,0) -> 0 | AJ28: =IF(AH28=AB28,AB28,0) -> 8 | AK28: =IF(SUM(AI28:AJ28)<=0,AB28,0) -> 0 | AL28: =IF(AI28=AB28,0,AJ28) -> 8 | AR28: 7 | AS28: G | AT28: VG | AU28: G | AV28: G | AW28: G | AX28: G | AY28: E | AZ28: A | BA28: A | BF28: =AA14 -> 7 | BG28: =AA15 -> 8 | GB28: 30 | GC28: S | GH28: Y | GR28: P | GS28: 8 | GU28: 15 | GV28: √ | HG28: 43846 | HH28: =TEXT(HG28,"DD-MMM") -> 16-Jan | HI28: Capricorn | HJ28: Earth | HK28: =HI28&" - "&HJ28 -> Capricorn - Earth
C29: 7 | D29: =IF(ISERROR(INDEX(GB:GB,MATCH(D28,$GB$1:$GB$33,1)+1,1)),"",INDEX(GB:GB,MATCH(D28,$GB$1:$GB$33,1)+1,1)) -> 38 | E29: =IF(ISERROR(INDEX(GB:GB,MATCH(E28,$GB$1:$GB$100,1)+1,1)),"",INDEX(GB:GB,MATCH(E28,$GB$1:$GB$100,1)+1,1)) -> 64 | G29: =MOD(D29-1,9)+1 -> 2 | H29: =MOD(E29-1,9)+1 -> 1 | J29: =INDEX($AR$21:$BA$32,MATCH($G29,$AR$21:$BA$21,0),MATCH($J$21,$AR$21:$AR$32,0)) -> VG | K29: =INDEX($AR$21:$BA$32,MATCH($G29,$AR$21:$BA$21,0),MATCH($K$21,$AR$21:$AR$32,0)) -> A | L29: =INDEX($AR$21:$BA$32,MATCH($H29,$AR$21:$BA$21,0),MATCH($L$21,$AR$21:$AR$32,0)) -> G | M29: =INDEX($AR$21:$BA$32,MATCH($H29,$AR$21:$BA$21,0),MATCH($M$21,$AR$21:$AR$32,0)) -> F | AB29: 9 | AE29: =IFERROR(HLOOKUP(AB29,C15:T15,1,0),0) -> 0 | AF29: =IFERROR(HLOOKUP(AB29,C17:T17,1,0),0) -> 0 | AG29: =IFERROR(HLOOKUP(AB29,C19:T19,1,0),0) -> 0 | AH29: =IFERROR(VLOOKUP(AB29,AI12:AI17,1,0),0) -> 0 | AI29: =IF(SUM(AE29:AG29)>=AB29,AB29,0) -> 0 | AJ29: =IF(AH29=AB29,AB29,0) -> 0 | AK29: =IF(SUM(AI29:AJ29)<=0,AB29,0) -> 9 | AL29: =IF(AI29=AB29,0,AJ29) -> 0 | AR29: 8 | AS29: F | AT29: A | AU29: G | AV29: A | AW29: VG | AX29: G | AY29: A | AZ29: E | BA29: SA | BE29: 1 | BF29: =INDEX($AR$21:$BA$32,MATCH($BE29,$AR$21:$BA$21,0),MATCH($BF$28,$AR$21:$AR$32,0)) -> G | BG29: =INDEX($AR$21:$BA$32,MATCH($BE29,$AR$21:$BA$21,0),MATCH($BG$28,$AR$21:$AR$32,0)) -> F | BI29: 1 | BJ29: 10 | BK29: 19 | BL29: 28 | BM29: 37 | BN29: 46 | BP29: 1 | BQ29: A | BR29: I | BS29: J | BT29: Q | BU29: Y | GB29: 32 | GC29: G | GR29: Q | GS29: 1 | GU29: 16 | GV29: X | GY29: Vowels | GZ29: a | HA29: e | HB29: i | HC29: o | HD29: u | HG29: 43847 | HH29: =TEXT(HG29,"DD-MMM") -> 17-Jan | HI29: Capricorn | HJ29: Earth | HK29: =HI29&" - "&HJ29 -> Capricorn - Earth
C30: 8 | D30: =IF(ISERROR(INDEX(GB:GB,MATCH(D29,$GB$1:$GB$33,1)+1,1)),"",INDEX(GB:GB,MATCH(D29,$GB$1:$GB$33,1)+1,1)) -> 38 | E30: =IF(ISERROR(INDEX(GB:GB,MATCH(E29,$GB$1:$GB$100,1)+1,1)),"",INDEX(GB:GB,MATCH(E29,$GB$1:$GB$100,1)+1,1)) -> 66 | G30: =MOD(D30-1,9)+1 -> 2 | H30: =MOD(E30-1,9)+1 -> 3 | J30: =INDEX($AR$21:$BA$32,MATCH($G30,$AR$21:$BA$21,0),MATCH($J$21,$AR$21:$AR$32,0)) -> VG | K30: =INDEX($AR$21:$BA$32,MATCH($G30,$AR$21:$BA$21,0),MATCH($K$21,$AR$21:$AR$32,0)) -> A | L30: =INDEX($AR$21:$BA$32,MATCH($H30,$AR$21:$BA$21,0),MATCH($L$21,$AR$21:$AR$32,0)) -> G | M30: =INDEX($AR$21:$BA$32,MATCH($H30,$AR$21:$BA$21,0),MATCH($M$21,$AR$21:$AR$32,0)) -> G | AR30: 9 | AS30: A | AT30: A | AU30: G | AV30: SA | AW30: F | AX30: G | AY30: A | AZ30: SA | BA30: E | BE30: 2 | BF30: =INDEX($AR$21:$BA$32,MATCH($BE30,$AR$21:$BA$21,0),MATCH($BF$28,$AR$21:$AR$32,0)) -> VG | BG30: =INDEX($AR$21:$BA$32,MATCH($BE30,$AR$21:$BA$21,0),MATCH($BG$28,$AR$21:$AR$32,0)) -> A | BI30: 2 | BJ30: 11 | BK30: 20 | BL30: 29 | BM30: 38 | BN30: 47 | BP30: 2 | BQ30: B | BR30: K | BS30: R | GB30: 33 | GC30: G | GR30: R | GS30: 2 | GU30: 17 | GV30: √ | GY30: Vowels | GZ30: a | HA30: e | HB30: i | HC30: o | HD30: u | HG30: 43848 | HH30: =TEXT(HG30,"DD-MMM") -> 18-Jan | HI30: Capricorn | HJ30: Earth | HK30: =HI30&" - "&HJ30 -> Capricorn - Earth
C31: 9 | D31: =IF(ISERROR(INDEX(GB:GB,MATCH(D30,$GB$1:$GB$33,1)+1,1)),"",INDEX(GB:GB,MATCH(D30,$GB$1:$GB$33,1)+1,1)) -> 38 | E31: =IF(ISERROR(INDEX(GB:GB,MATCH(E30,$GB$1:$GB$100,1)+1,1)),"",INDEX(GB:GB,MATCH(E30,$GB$1:$GB$100,1)+1,1)) -> 68 | G31: =MOD(D31-1,9)+1 -> 2 | H31: =MOD(E31-1,9)+1 -> 5 | J31: =INDEX($AR$21:$BA$32,MATCH($G31,$AR$21:$BA$21,0),MATCH($J$21,$AR$21:$AR$32,0)) -> VG | K31: =INDEX($AR$21:$BA$32,MATCH($G31,$AR$21:$BA$21,0),MATCH($K$21,$AR$21:$AR$32,0)) -> A | L31: =INDEX($AR$21:$BA$32,MATCH($H31,$AR$21:$BA$21,0),MATCH($L$21,$AR$21:$AR$32,0)) -> G | M31: =INDEX($AR$21:$BA$32,MATCH($H31,$AR$21:$BA$21,0),MATCH($M$21,$AR$21:$AR$32,0)) -> VG | BE31: 3 | BF31: =INDEX($AR$21:$BA$32,MATCH($BE31,$AR$21:$BA$21,0),MATCH($BF$28,$AR$21:$AR$32,0)) -> G | BG31: =INDEX($AR$21:$BA$32,MATCH($BE31,$AR$21:$BA$21,0),MATCH($BG$28,$AR$21:$AR$32,0)) -> G | BI31: 3 | BJ31: 12 | BK31: 21 | BL31: 30 | BM31: 39 | BN31: 48 | BP31: 3 | BQ31: C | BR31: G | BS31: L | BT31: S | GB31: 34 | GC31: S | GR31: S | GS31: 3 | GU31: 18 | GV31: X | GZ31: 1 | HA31: 5 | HB31: 1 | HC31: 7 | HD31: 6 | HG31: 43849 | HH31: =TEXT(HG31,"DD-MMM") -> 19-Jan | HI31: Capricorn | HJ31: Earth | HK31: =HI31&" - "&HJ31 -> Capricorn - Earth
C32: 10 | D32: =IF(ISERROR(INDEX(GB:GB,MATCH(D31,$GB$1:$GB$33,1)+1,1)),"",INDEX(GB:GB,MATCH(D31,$GB$1:$GB$33,1)+1,1)) -> 38 | E32: =IF(ISERROR(INDEX(GB:GB,MATCH(E31,$GB$1:$GB$100,1)+1,1)),"",INDEX(GB:GB,MATCH(E31,$GB$1:$GB$100,1)+1,1)) -> 69 | G32: =MOD(D32-1,9)+1 -> 2 | H32: =MOD(E32-1,9)+1 -> 6 | J32: =INDEX($AR$21:$BA$32,MATCH($G32,$AR$21:$BA$21,0),MATCH($J$21,$AR$21:$AR$32,0)) -> VG | K32: =INDEX($AR$21:$BA$32,MATCH($G32,$AR$21:$BA$21,0),MATCH($K$21,$AR$21:$AR$32,0)) -> A | L32: =INDEX($AR$21:$BA$32,MATCH($H32,$AR$21:$BA$21,0),MATCH($L$21,$AR$21:$AR$32,0)) -> G | M32: =INDEX($AR$21:$BA$32,MATCH($H32,$AR$21:$BA$21,0),MATCH($M$21,$AR$21:$AR$32,0)) -> G | BE32: 4 | BF32: =INDEX($AR$21:$BA$32,MATCH($BE32,$AR$21:$BA$21,0),MATCH($BF$28,$AR$21:$AR$32,0)) -> G | BG32: =INDEX($AR$21:$BA$32,MATCH($BE32,$AR$21:$BA$21,0),MATCH($BG$28,$AR$21:$AR$32,0)) -> A | BI32: 4 | BJ32: 13 | BK32: 22 | BL32: 31 | BM32: 40 | BN32: 49 | BP32: 4 | BQ32: D | BR32: M | BS32: T | GB32: 36 | GC32: G | GR32: T | GS32: 4 | GU32: 19 | GV32: * | HG32: 43850 | HH32: =TEXT(HG32,"DD-MMM") -> 20-Jan | HI32: Aquarius | HJ32: Air | HK32: =HI32&" - "&HJ32 -> Aquarius - Air
AB33: New Aspects / Compatibility | AI33: =IF(LEN(AA35)>1,LEFT(AA35,1)+RIGHT(AA35,1),AA35) -> 7 | BE33: 5 | BF33: =INDEX($AR$21:$BA$32,MATCH($BE33,$AR$21:$BA$21,0),MATCH($BF$28,$AR$21:$AR$32,0)) -> G | BG33: =INDEX($AR$21:$BA$32,MATCH($BE33,$AR$21:$BA$21,0),MATCH($BG$28,$AR$21:$AR$32,0)) -> VG | BI33: 5 | BJ33: 14 | BK33: 23 | BL33: 32 | BM33: 41 | BN33: 50 | BP33: 5 | BQ33: E | BR33: H | BS33: N | BT33: X | GB33: 37 | GC33: G | GR33: U | GS33: 6 | GU33: 20 | GV33: √ | GX33: FN Vowel | GY33: =(GZ33*GZ34)+(HA33*HA34)+(HB33*HB34)+(HC33*HC34)+(HD33*HD34) -> 2 | GZ33: =IFERROR((HLOOKUP(GZ30,C35:T36,2,0)),0) -> 0 | HA33: =IFERROR((HLOOKUP(HA30,C35:T36,2,0)),0) -> 0 | HB33: =IFERROR((HLOOKUP(HB30,C35:T36,2,0)),0) -> 1 | HC33: =IFERROR((HLOOKUP(HC30,C35:T36,2,0)),0) -> 0 | HD33: =IFERROR((HLOOKUP(HD30,C35:T36,2,0)),0) -> 0 | HG33: 43851 | HH33: =TEXT(HG33,"DD-MMM") -> 21-Jan | HI33: Aquarius | HJ33: Air | HK33: =HI33&" - "&HJ33 -> Aquarius - Air
A34: Corrected Name | Y34: New Core | AB34: With BD | AC34: With LP | AI34: =IF(LEN(AA36)>1,LEFT(AA36,1)+RIGHT(AA36,1),AA36) -> 8 | BE34: 6 | BF34: =INDEX($AR$21:$BA$32,MATCH($BE34,$AR$21:$BA$21,0),MATCH($BF$28,$AR$21:$AR$32,0)) -> G | BG34: =INDEX($AR$21:$BA$32,MATCH($BE34,$AR$21:$BA$21,0),MATCH($BG$28,$AR$21:$AR$32,0)) -> G | BI34: 6 | BJ34: 15 | BK34: 24 | BL34: 33 | BM34: 42 | BN34: 51 | BP34: 6 | BQ34: U | BR34: V | BS34: W | GB34: 38 | GC34: S | GR34: V | GS34: 6 | GU34: 21 | GV34: * | GZ34: =COUNTIFS(C35:T35,GZ30) -> 0 | HA34: =COUNTIFS(C35:T35,HA30) -> 0 | HB34: =COUNTIFS(C35:T35,HB30) -> 2 | HC34: =COUNTIFS(C35:T35,HC30) -> 0 | HD34: =COUNTIFS(C35:T35,HD30) -> 0 | HG34: 43852 | HH34: =TEXT(HG34,"DD-MMM") -> 22-Jan | HI34: Aquarius | HJ34: Air | HK34: =HI34&" - "&HJ34 -> Aquarius - Air
A35: First Name | B35: Kriishh | C35: =MID($B35,COLUMNS($B$13:B$13),1) -> K | D35: =MID($B35,COLUMNS($B$13:C$13),1) -> r | E35: =MID($B35,COLUMNS($B$13:D$13),1) -> i | F35: =MID($B35,COLUMNS($B$13:E$13),1) -> i | G35: =MID($B35,COLUMNS($B$13:F$13),1) -> s | H35: =MID($B35,COLUMNS($B$13:G$13),1) -> h | I35: =MID($B35,COLUMNS($B$13:H$13),1) -> h | J35: =MID($B35,COLUMNS($B$13:I$13),1) | ... T35: =MID($B35,COLUMNS($B$13:S$13),1) | Y35: BD | Z35: =C$5 -> 7 | AA35: =C6 -> 7 | AB35: =IF(D10<=35,"Active",0) -> 0 | AC35: =IF(D10>35,"Active",0) -> Active | AI35: =IF(LEN(AA37)>1,LEFT(AA37,1)+RIGHT(AA37,1),AA37) -> 1 | AS35: Number Series | BE35: 7 | BF35: =INDEX($AR$21:$BA$32,MATCH($BE35,$AR$21:$BA$21,0),MATCH($BF$28,$AR$21:$AR$32,0)) -> E | BG35: =INDEX($AR$21:$BA$32,MATCH($BE35,$AR$21:$BA$21,0),MATCH($BG$28,$AR$21:$AR$32,0)) -> A | BI35: 7 | BJ35: 16 | BK35: 25 | BL35: 34 | BM35: 43 | BN35: 52 | BP35: 7 | BQ35: O | BR35: Z | GB35: 39 | GC35: S | GR35: W | GS35: 6 | GU35: 22 | GV35: X | HG35: 43853 | HH35: =TEXT(HG35,"DD-MMM") -> 23-Jan | HI35: Aquarius | HJ35: Air | HK35: =HI35&" - "&HJ35 -> Aquarius - Air
C36: =IFERROR(VLOOKUP(C35,GR:GS,2,0),0) -> 2 | D36: =IFERROR(VLOOKUP(D35,GR:GS,2,0),0) -> 2 | E36: =IFERROR(VLOOKUP(E35,GR:GS,2,0),0) -> 1 | F36: =IFERROR(VLOOKUP(F35,GR:GS,2,0),0) -> 1 | G36: =IFERROR(VLOOKUP(G35,GR:GS,2,0),0) -> 3 | H36: =IFERROR(VLOOKUP(H35,GR:GS,2,0),0) -> 5 | I36: =IFERROR(VLOOKUP(I35,GR:GS,2,0),0) -> 5 | J36: =IFERROR(VLOOKUP(J35,GR:GS,2,0),0) -> 0 | ... T36: =IFERROR(VLOOKUP(T35,GR:GS,2,0),0) -> 0 | U36: =SUM(C36:T36) -> 19 | V36: =IF(U36<10,U36,((LEFT(U36,1))+(RIGHT(U36,1)))) -> 10 | W36: FN | X36: =IF(U36>52,VLOOKUP(V36,GU:GV,2,0),VLOOKUP(U36,GU:GV,2,0)) -> * | Y36: LP | Z36: =I$5+F$5+C$5 -> 17 | AA36: =C7 -> 8 | AI36: =IF(LEN(AA38)>1,LEFT(AA38,1)+RIGHT(AA38,1),AA38) -> 6 | AS36: 1 | AT36: 2 | AU36: 3 | AV36: 4 | AW36: 5 | AX36: 6 | AY36: 7 | AZ36: 8 | BA36: 9 | BE36: 8 | BF36: =INDEX($AR$21:$BA$32,MATCH($BE36,$AR$21:$BA$21,0),MATCH($BF$28,$AR$21:$AR$32,0)) -> A | BG36: =INDEX($AR$21:$BA$32,MATCH($BE36,$AR$21:$BA$21,0),MATCH($BG$28,$AR$21:$AR$32,0)) -> E | BI36: 8 | BJ36: 17 | BK36: 26 | BL36: 35 | BM36: 44 | BP36: 8 | BQ36: F | BR36: P | GB36: 41 | GC36: G | GR36: X | GS36: 5 | GU36: 23 | GV36: * | GX36: MN Vovel | GY36: =(GZ36*GZ37)+(HA36*HA37)+(HB36*HB37)+(HC36*HC37)+(HD36*HD37) -> 0 | GZ36: =IFERROR((HLOOKUP(GZ30,C37:T38,2,0)),0) -> 0 | HA36: =IFERROR((HLOOKUP(HA30,C37:T38,2,0)),0) -> 0 | HB36: =IFERROR((HLOOKUP(HB30,C37:T38,2,0)),0) -> 0 | HC36: =IFERROR((HLOOKUP(HC30,C37:T38,2,0)),0) -> 0 | HD36: =IFERROR((HLOOKUP(HD30,C37:T38,2,0)),0) -> 0 | HG36: 43854 | HH36: =TEXT(HG36,"DD-MMM") -> 24-Jan | HI36: Aquarius | HJ36: Air | HK36: =HI36&" - "&HJ36 -> Aquarius - Air
A37: Middle Name | B37: C | C37: =MID($B37,COLUMNS($B$13:B$13),1) -> C | D37: =MID($B37,COLUMNS($B$13:C$13),1) | E37: =MID($B37,COLUMNS($B$13:D$13),1) | F37: =MID($B37,COLUMNS($B$13:E$13),1) | G37: =MID($B37,COLUMNS($B$13:F$13),1) | H37: =MID($B37,COLUMNS($B$13:G$13),1) | I37: =MID($B37,COLUMNS($B$13:H$13),1) | J37: =MID($B37,COLUMNS($B$13:I$13),1) | ... T37: =MID($B37,COLUMNS($B$13:S$13),1) | Y37: FN | Z37: =U36 -> 19 | AA37: =MOD(Z37-1,9)+1 -> 1 | AB37: =INDEX(GH$14:GP$22,MATCH(IF(LEN(AA$35)>1,LEFT(AA$35,1)+RIGHT(AA$35,1),AA$35),GG$14:GG$22,0),MATCH(IF(LEN(AA37)>1,LEFT(AA37,1)+RIGHT(AA37,1),AA37),GH$13:GP$13,0)) -> G | AC37: =INDEX(GH$14:GP$22,MATCH(IF(LEN(AA$36)>1,LEFT(AA$36,1)+RIGHT(AA$36,1),AA$36),GG$14:GG$22,0),MATCH(IF(LEN(AA37)>1,LEFT(AA37,1)+RIGHT(AA37,1),AA37),GH$13:GP$13,0)) -> F | AI37: =IF(LEN(AA39)>1,LEFT(AA39,1)+RIGHT(AA39,1),AA39) -> 8 | AS37: 1 | AT37: 2 | AU37: 3 | AV37: 4 | AW37: 5 | AX37: 6 | AY37: 7 | AZ37: 8 | BA37: 9 | BE37: 9 | BF37: =INDEX($AR$21:$BA$32,MATCH($BE37,$AR$21:$BA$21,0),MATCH($BF$28,$AR$21:$AR$32,0)) -> A | BG37: =INDEX($AR$21:$BA$32,MATCH($BE37,$AR$21:$BA$21,0),MATCH($BG$28,$AR$21:$AR$32,0)) -> SA | BI37: 9 | BJ37: 18 | BK37: 27 | BL37: 36 | BM37: 45 | GB37: 42 | GC37: G | GR37: Y | GS37: 1 | GU37: 24 | GV37: * | GZ37: =COUNTIFS(C37:T37,GZ30) -> 0 | HA37: =COUNTIFS(C37:T37,HA30) -> 0 | HB37: =COUNTIFS(C37:T37,HB30) -> 0 | HC37: =COUNTIFS(C37:T37,HC30) -> 0 | HD37: =COUNTIFS(C37:T37,HD30) -> 0 | HG37: 43855 | HH37: =TEXT(HG37,"DD-MMM") -> 25-Jan | HI37: Aquarius | HJ37: Air | HK37: =HI37&" - "&HJ37 -> Aquarius - Air
C38: =IFERROR(VLOOKUP(C37,GR:GS,2,0),0) -> 3 | D38: =IFERROR(VLOOKUP(D37,GR:GS,2,0),0) -> 0 | E38: =IFERROR(VLOOKUP(E37,GR:GS,2,0),0) -> 0 | F38: =IFERROR(VLOOKUP(F37,GR:GS,2,0),0) -> 0 | G38: =IFERROR(VLOOKUP(G37,GR:GS,2,0),0) -> 0 | H38: =IFERROR(VLOOKUP(H37,GR:GS,2,0),0) -> 0 | I38: =IFERROR(VLOOKUP(I37,GR:GS,2,0),0) -> 0 | J38: =IFERROR(VLOOKUP(J37,GR:GS,2,0),0) -> 0 | ... T38: =IFERROR(VLOOKUP(T37,GR:GS,2,0),0) -> 0 | U38: =SUM(C38:T38) -> 3 | V38: =IF(U38<10,U38,((LEFT(U38,1))+(RIGHT(U38,1)))) -> 3 | Y38: EXP | Z38: =U41 -> 42 | AA38: =MOD(Z38-1,9)+1 -> 6 | AB38: =INDEX(GH$14:GP$22,MATCH(IF(LEN(AA$35)>1,LEFT(AA$35,1)+RIGHT(AA$35,1),AA$35),GG$14:GG$22,0),MATCH(IF(LEN(AA38)>1,LEFT(AA38,1)+RIGHT(AA38,1),AA38),GH$13:GP$13,0)) -> G | AC38: =INDEX(GH$14:GP$22,MATCH(IF(LEN(AA$36)>1,LEFT(AA$36,1)+RIGHT(AA$36,1),AA$36),GG$14:GG$22,0),MATCH(IF(LEN(AA38)>1,LEFT(AA38,1)+RIGHT(AA38,1),AA38),GH$13:GP$13,0)) -> G | AI38: =IF(LEN(AA40)>1,LEFT(AA40,1)+RIGHT(AA40,1),AA40) -> 7 | AS38: 10 | AT38: 11 | AU38: 12 | AV38: 13 | AW38: 14 | AX38: 15 | AY38: 16 | AZ38: 17 | BA38: 18 | GB38: 43 | GC38: G | GR38: Z | GS38: 7 | GU38: 25 | GV38: √ | HG38: 43856 | HH38: =TEXT(HG38,"DD-MMM") -> 26-Jan | HI38: Aquarius | HJ38: Air | HK38: =HI38&" - "&HJ38 -> Aquarius - Air
A39: Last Name | B39: Karrpe | C39: =MID($B39,COLUMNS($B$13:B$13),1) -> K | D39: =MID($B39,COLUMNS($B$13:C$13),1) -> a | E39: =MID($B39,COLUMNS($B$13:D$13),1) -> r | F39: =MID($B39,COLUMNS($B$13:E$13),1) -> r | G39: =MID($B39,COLUMNS($B$13:F$13),1) -> p | H39: =MID($B39,COLUMNS($B$13:G$13),1) -> e | I39: =MID($B39,COLUMNS($B$13:H$13),1) | J39: =MID($B39,COLUMNS($B$13:I$13),1) | ... T39: =MID($B39,COLUMNS($B$13:S$13),1) | Y39: SU | Z39: =GY33+GY39+GY36 -> 8 | AA39: =MOD(Z39-1,9)+1 -> 8 | AB39: =INDEX(GH$14:GP$22,MATCH(IF(LEN(AA$35)>1,LEFT(AA$35,1)+RIGHT(AA$35,1),AA$35),GG$14:GG$22,0),MATCH(IF(LEN(AA39)>1,LEFT(AA39,1)+RIGHT(AA39,1),AA39),GH$13:GP$13,0)) -> A | AC39: =INDEX(GH$14:GP$22,MATCH(IF(LEN(AA$36)>1,LEFT(AA$36,1)+RIGHT(AA$36,1),AA$36),GG$14:GG$22,0),MATCH(IF(LEN(AA39)>1,LEFT(AA39,1)+RIGHT(AA39,1),AA39),GH$13:GP$13,0)) -> E | AS39: 19 | AT39: 20 | AU39: 21 | AV39: 22 | AW39: 23 | AX39: 24 | AY39: 25 | AZ39: 26 | BA39: 27 | GB39: 45 | GC39: S | GR39: 1 | GS39: 1 | GU39: 26 | GV39: X | GX39: LN Vowel | GY39: =(GZ39*GZ40)+(HA39*HA40)+(HB39*HB40)+(HC39*HC40)+(HD39*HD40) -> 6 | GZ39: =IFERROR((HLOOKUP(GZ30,C39:T40,2,0)),0) -> 1 | HA39: =IFERROR((HLOOKUP(HA30,C39:T40,2,0)),0) -> 5 | HB39: =IFERROR((HLOOKUP(HB30,C39:T40,2,0)),0) -> 0 | HC39: =IFERROR((HLOOKUP(HC30,C39:T40,2,0)),0) -> 0 | HD39: =IFERROR((HLOOKUP(HD30,C39:T40,2,0)),0) -> 0 | HG39: 43857 | HH39: =TEXT(HG39,"DD-MMM") -> 27-Jan | HI39: Aquarius | HJ39: Air | HK39: =HI39&" - "&HJ39 -> Aquarius - Air
C40: =IFERROR(VLOOKUP(C39,GR:GS,2,0),0) -> 2 | D40: =IFERROR(VLOOKUP(D39,GR:GS,2,0),0) -> 1 | E40: =IFERROR(VLOOKUP(E39,GR:GS,2,0),0) -> 2 | F40: =IFERROR(VLOOKUP(F39,GR:GS,2,0),0) -> 2 | G40: =IFERROR(VLOOKUP(G39,GR:GS,2,0),0) -> 8 | H40: =IFERROR(VLOOKUP(H39,GR:GS,2,0),0) -> 5 | I40: =IFERROR(VLOOKUP(I39,GR:GS,2,0),0) -> 0 | J40: =IFERROR(VLOOKUP(J39,GR:GS,2,0),0) -> 0 | ... T40: =IFERROR(VLOOKUP(T39,GR:GS,2,0),0) -> 0 | U40: =SUM(C40:T40) -> 20 | V40: =IF(U40<10,U40,((LEFT(U40,1))+(RIGHT(U40,1)))) -> 2 | Y40: SS | Z40: =Z38-Z39 -> 34 | AA40: =MOD(Z40-1,9)+1 -> 7 | AB40: =INDEX(GH$14:GP$22,MATCH(IF(LEN(AA$35)>1,LEFT(AA$35,1)+RIGHT(AA$35,1),AA$35),GG$14:GG$22,0),MATCH(IF(LEN(AA40)>1,LEFT(AA40,1)+RIGHT(AA40,1),AA40),GH$13:GP$13,0)) -> E | AC40: =INDEX(GH$14:GP$22,MATCH(IF(LEN(AA$36)>1,LEFT(AA$36,1)+RIGHT(AA$36,1),AA$36),GG$14:GG$22,0),MATCH(IF(LEN(AA40)>1,LEFT(AA40,1)+RIGHT(AA40,1),AA40),GH$13:GP$13,0)) -> A | AE40: Karmic Number | AS40: 28 | AT40: 29 | AU40: 30 | AV40: 31 | AW40: 32 | AX40: 33 | AY40: 34 | AZ40: 35 | BA40: 36 | BF40: 55 | BG40: =MOD(BF40-1,9)+1 -> 1 | GB40: 46 | GC40: S | GR40: 2 | GS40: 2 | GU40: 27 | GV40: √ | GZ40: =COUNTIFS(C39:T39,GZ30) -> 1 | HA40: =COUNTIFS(C39:T39,HA30) -> 1 | HB40: =COUNTIFS(C39:T39,HB30) -> 0 | HC40: =COUNTIFS(C39:T39,HC30) -> 0 | HD40: =COUNTIFS(C39:T39,HD30) -> 0 | HG40: 43858 | HH40: =TEXT(HG40,"DD-MMM") -> 28-Jan | HI40: Aquarius | HJ40: Air | HK40: =HI40&" - "&HJ40 -> Aquarius - Air
U41: =U40+U38+U36 -> 42 | V41: =V36+V38+V40 -> 15 | W41: EXP | X41: =IF(U41>52,VLOOKUP(V41,GU:GV,2,0),VLOOKUP(U41,GU:GV,2,0)) -> √ | AB41: Hidden Passion | AE41: FN | AF41: MN | AG41: LN | AH41: Core | AI41: N | AJ41: C | AK41: KLs | AL41: MKLs | AS41: 37 | AT41: 38 | AU41: 39 | AV41: 40 | AW41: 41 | AX41: 42 | AY41: 43 | AZ41: 44 | BA41: 45 | BF41: 57 | BG41: =MOD(BF41-1,9)+1 -> 3 | GB41: 47 | GC41: S | GR41: 3 | GS41: 3 | GU41: 28 | GV41: X | HG41: 43859 | HH41: =TEXT(HG41,"DD-MMM") -> 29-Jan | HI41: Aquarius | HJ41: Air | HK41: =HI41&" - "&HJ41 -> Aquarius - Air
...

Sheet Master Calculator
B1: MM/DD/YYYY | C1: D | D1: D | F1: M | G1: M | I1: Y | J1: Y | K1: Y | L1: Y | Q1: BD | R1: LP | AH1: Compatibility Table
A2: Date of Birth | B2: 28884 | C2: =MID(A4,1,1) -> 2 | D2: =MID(A4,2,1) -> 9 | F2: =MID(A4,4,1) -> 0 | G2: =MID(A4,5,1) -> 1 | I2: =MID(A4,7,1) -> 1 | J2: =MID(A4,8,1) -> 9 | K2: =MID(A4,9,1) -> 7 | L2: =MID(A4,10,1) -> 9 | Q2: =C6 -> 2 | R2: =C7 -> 2 | AI2: 1 | AJ2: 2 | AK2: 3 | AL2: 4 | AM2: 5 | AN2: 6 | AO2: 7 | AP2: 8 | AQ2: 9
A3: =TEXT(B2,("DD-MMM")) -> 29-Jan | I3: =I2&J2&K2&L2 -> 1979 | L3: =SUMPRODUCT(1*MID(I3,ROW(INDIRECT("1:"&LEN(I3))),1)) -> 26 | P3: 1 | Q3: =INDEX($AH$2:$AQ$11,MATCH(P3,$AH$2:$AQ$2,0),MATCH($Q$2,$AH$2:$AH$11,0)) -> G | R3: =INDEX($AH$2:$AQ$11,MATCH(P3,$AH$2:$AQ$2,0),MATCH($R$2,$AH$2:$AH$11,0)) -> G | T3: 1 | U3: 10 | V3: 19 | W3: 28 | X3: 37 | Y3: 46 | AA3: 1 | AB3: A | AC3: I | AD3: J | AE3: Q | AF3: Y | AH3: 1 | AI3: E | AJ3: G | AK3: G | AL3: F | AM3: G | AN3: F | AO3: G | AP3: F | AQ3: A
A4: =TEXT(B2,"DD-MM-YYYY") -> 29-01-1979 | B4: Zodiac & Element | C4: BD | F4: BM | I4: BY | N4: Age | P4: 2 | Q4: =INDEX($AH$2:$AQ$11,MATCH(P4,$AH$2:$AQ$2,0),MATCH($Q$2,$AH$2:$AH$11,0)) -> E | R4: =INDEX($AH$2:$AQ$11,MATCH(P4,$AH$2:$AQ$2,0),MATCH($R$2,$AH$2:$AH$11,0)) -> E | T4: 2 | U4: 11 | V4: 20 | W4: 29 | X4: 38 | Y4: 47 | AA4: 2 | AB4: B | AC4: K | AD4: R | AH4: 2 | AI4: G | AJ4: E | AK4: G | AL4: G | AM4: F | AN4: G | AO4: VG | AP4: A | AQ4: A
B5: =VLOOKUP(A3,HH:HK,4,0) -> Aquarius - Air | C5: =C2+D2 -> 11 | F5: =F2+G2 -> 1 | I5: =SUMPRODUCT(1*MID(L3,ROW(INDIRECT("1:"&LEN(L3))),1)) -> 8 | N5: =(TODAY()-B2)/365 -> 46.471233 | P5: 3 | Q5: =INDEX($AH$2:$AQ$11,MATCH(P5,$AH$2:$AQ$2,0),MATCH($Q$2,$AH$2:$AH$11,0)) -> G | R5: =INDEX($AH$2:$AQ$11,MATCH(P5,$AH$2:$AQ$2,0),MATCH($R$2,$AH$2:$AH$11,0)) -> G | T5: 3 | U5: 12 | V5: 21 | W5: 30 | X5: 39 | Y5: 48 | AA5: 3 | AB5: C | AC5: G | AD5: L | AE5: S | AH5: 3 | AI5: G | AJ5: G | AK5: E | AL5: A | AM5: G | AN5: A | AO5: G | AP5: G | AQ5: G
B6: BD | C6: =IF(LEN(C5)>1,LEFT(C5,1)+RIGHT(C5,1),C5) -> 2 | F6: =IF(LEN(F5)>1,LEFT(F5,1)+RIGHT(F5,1),F5) -> 1 | I6: =SUMPRODUCT(1*MID(I5,ROW(INDIRECT("1:"&LEN(I5))),1)) -> 8 | P6: 4 | Q6: =INDEX($AH$2:$AQ$11,MATCH(P6,$AH$2:$AQ$2,0),MATCH($Q$2,$AH$2:$AH$11,0)) -> G | R6: =INDEX($AH$2:$AQ$11,MATCH(P6,$AH$2:$AQ$2,0),MATCH($R$2,$AH$2:$AH$11,0)) -> G | T6: 4 | U6: 13 | V6: 22 | W6: 31 | X6: 40 | Y6: 49 | AA6: 4 | AB6: D | AC6: M | AD6: T | AH6: 4 | AI6: F | AJ6: G | AK6: A | AL6: E | AM6: G | AN6: G | AO6: G | AP6: A | AQ6: SA
B7: LP | C7: =MOD((C6+F6+I6)-1,9)+1 -> 2 | P7: 5 | Q7: =INDEX($AH$2:$AQ$11,MATCH(P7,$AH$2:$AQ$2,0),MATCH($Q$2,$AH$2:$AH$11,0)) -> F | R7: =INDEX($AH$2:$AQ$11,MATCH(P7,$AH$2:$AQ$2,0),MATCH($R$2,$AH$2:$AH$11,0)) -> F | T7: 5 | U7: 14 | V7: 23 | W7: 32 | X7: 41 | Y7: 50 | AA7: 5 | AB7: E | AC7: H | AD7: N | AE7: X | AH7: 5 | AI7: G | AJ7: F | AK7: G | AL7: G | AM7: E | AN7: F | AO7: G | AP7: VG | AQ7: F
P8: 6 | Q8: =INDEX($AH$2:$AQ$11,MATCH(P8,$AH$2:$AQ$2,0),MATCH($Q$2,$AH$2:$AH$11,0)) -> G | R8: =INDEX($AH$2:$AQ$11,MATCH(P8,$AH$2:$AQ$2,0),MATCH($R$2,$AH$2:$AH$11,0)) -> G | T8: 6 | U8: 15 | V8: 24 | W8: 33 | X8: 42 | Y8: 51 | AA8: 6 | AB8: U | AC8: V | AD8: W | AH8: 6 | AI8: F | AJ8: G | AK8: A | AL8: G | AM8: F | AN8: E | AO8: G | AP8: G | AQ8: G
A9: Gender | B9: female | P9: 7 | Q9: =INDEX($AH$2:$AQ$11,MATCH(P9,$AH$2:$AQ$2,0),MATCH($Q$2,$AH$2:$AH$11,0)) -> VG | R9: =INDEX($AH$2:$AQ$11,MATCH(P9,$AH$2:$AQ$2,0),MATCH($R$2,$AH$2:$AH$11,0)) -> VG | T9: 7 | U9: 16 | V9: 25 | W9: 34 | X9: 43 | Y9: 52 | AA9: 7 | AB9: O | AC9: Z | AH9: 7 | AI9: G | AJ9: VG | AK9: G | AL9: G | AM9: G | AN9: G | AO9: E | AP9: A | AQ9: A
D10: Balance No. | E10: =LEFT(B16,1) -> A | F10: =LEFT(B18,1) -> M | G10: =VLOOKUP(E10,$GR$12:$GS$48,2,0)+VLOOKUP(F10,$GR$12:$GS$48,2,0) -> 5 | P10: 8 | Q10: =INDEX($AH$2:$AQ$11,MATCH(P10,$AH$2:$AQ$2,0),MATCH($Q$2,$AH$2:$AH$11,0)) -> A | R10: =INDEX($AH$2:$AQ$11,MATCH(P10,$AH$2:$AQ$2,0),MATCH($R$2,$AH$2:$AH$11,0)) -> A | T10: 8 | U10: 17 | V10: 26 | W10: 35 | X10: 44 | AA10: 8 | AB10: F | AC10: P | AH10: 8 | AI10: F | AJ10: A | AK10: G | AL10: A | AM10: VG | AN10: G | AO10: A | AP10: E | AQ10: SA
D11: Attitude No. | E11: =C5 -> 11 | F11: =F5 -> 1 | G11: =MOD(E11+F11-1,9)+1 -> 3 | P11: 9 | Q11: =INDEX($AH$2:$AQ$11,MATCH(P11,$AH$2:$AQ$2,0),MATCH($Q$2,$AH$2:$AH$11,0)) -> A | R11: =INDEX($AH$2:$AQ$11,MATCH(P11,$AH$2:$AQ$2,0),MATCH($R$2,$AH$2:$AH$11,0)) -> A | T11: 9 | U11: 18 | V11: 27 | W11: 36 | X11: 45 | AH11: 9 | AI11: A | AJ11: A | AK11: G | AL11: SA | AM11: F | AN11: G | AO11: A | AP11: SA | AQ11: E
AH12: E - Excelent | VG - Very Good | G - Good | F - Fair | A - Avoid | SA - Super Avoid | GB12: No | GC12: Rank | GG12: Compatibility Table | GR12: Alphabet | GS12: Number | GU12: Compound Numbers | GY12: Vowels | GZ12: a | HA12: e | HB12: i | HC12: o | HD12: u | HG12: Date | HH12: Date | HI12: Zodiac | HJ12: Element | HK12: =HI12&" - "&HJ12 -> Zodiac - Element
GB13: 5 | GC13: G | GH13: 1 | GI13: 2 | GJ13: 3 | GK13: 4 | GL13: 5 | GM13: 6 | GN13: 7 | GO13: 8 | GP13: 9 | GR13: A | GS13: 1 | GU13: No | GV13: Rank | GZ13: 1 | HA13: 5 | HB13: 1 | HC13: 7 | HD13: 6 | HG13: 43831 | HH13: =TEXT(HG13,"DD-MMM") -> 01-Jan | HI13: Capricorn | HJ13: Earth | HK13: =HI13&" - "&HJ13 -> Capricorn - Earth
GB14: 6 | GC14: G | GG14: 1 | GH14: E | GI14: G | GJ14: G | GK14: F | GL14: G | GM14: F | GN14: G | GO14: F | GP14: A | GR14: B | GS14: 2 | GU14: 1 | GV14: X | HG14: 43832 | HH14: =TEXT(HG14,"DD-MMM") -> 02-Jan | HI14: Capricorn | HJ14: Earth | HK14: =HI14&" - "&HJ14 -> Capricorn - Earth
A15: Current Name | M15: Old Aspects / Compatibility | Q15: No | R15: KL | S15: MKL | U15: HP | AD15: BD | AE15: LP | AJ15: BD | AK15: LP | GB15: 10 | GC15: G | GG15: 2 | GH15: G | GI15: E | GJ15: G | GK15: G | GL15: F | GM15: G | GN15: VG | GO15: A | GP15: A | GR15: C | GS15: 3 | GU15: 2 | GV15: X | GX15: FN Vowel | GY15: =(GZ15*GZ16)+(HA15*HA16)+(HB15*HB16)+(HC15*HC16)+(HD15*HD16) -> 0 | GZ15: =IFERROR((HLOOKUP(GZ12,C14:T15,2,0)),0) -> 0 | HA15: =IFERROR((HLOOKUP(HA12,C14:T15,2,0)),0) -> 0 | HB15: =IFERROR((HLOOKUP(HB12,C14:T15,2,0)),0) -> 0 | HC15: =IFERROR((HLOOKUP(HC12,C14:T15,2,0)),0) -> 0 | HD15: =IFERROR((HLOOKUP(HD12,C14:T15,2,0)),0) -> 0 | HG15: 43833 | HH15: =TEXT(HG15,"DD-MMM") -> 03-Jan | HI15: Capricorn | HJ15: Earth | HK15: =HI15&" - "&HJ15 -> Capricorn - Earth
A16: First Name | B16: ACHARYA | D16: =MasterTables!AM2 -> 14 | E16: =IF(D16<10,D16,((LEFT(D16,1))+(RIGHT(D16,1)))) -> 5 | F16: =MasterTables!AO2 -> FN | G16: =MasterTables!AP2 -> √ | J16: Current | M16: With BD | N16: With LP | Q16: 1 | R16: =MasterTables!CF21 -> 0 | S16: =MasterTables!CG21 -> 0 | U16: =MasterTables!BX21 -> 6 | AB16: FN | AD16: =C6 -> 2 | AE16: =C7 -> 2 | AH16: EXP | AJ16: =C6 -> 2 | AK16: =C7 -> 2 | GB16: 12 | GC16: G | GG16: 3 | GH16: G | GI16: G | GJ16: E | GK16: A | GL16: G | GM16: A | GN16: G | GO16: G | GP16: G | GR16: D | GS16: 4 | GU16: 3 | GV16: X | GZ16: =COUNTIFS(C14:T14,GZ12) -> 0 | HA16: =COUNTIFS(C14:T14,HA12) -> 0 | HB16: =COUNTIFS(C14:T14,HB12) -> 0 | HC16: =COUNTIFS(C14:T14,HC12) -> 0 | HD16: =COUNTIFS(C14:T14,HD12) -> 0 | HG16: 43834 | HH16: =TEXT(HG16,"DD-MMM") -> 04-Jan | HI16: Capricorn | HJ16: Earth | HK16: =HI16&" - "&HJ16 -> Capricorn - Earth
A17: Middle Name | B17: KAMLESH | D17: =MasterTables!AM4 -> 23 | E17: =IF(D17<10,D17,((LEFT(D17,1))+(RIGHT(D17,1)))) -> 5 | J17: BD | L17: =C6 -> 2 | M17: =IF(N5<=35,"Active",0) -> 0 | N17: =IF(N5>35,"Active",0) -> Active | Q17: 2 | R17: =MasterTables!CF22 -> 0 | S17: =MasterTables!CG22 -> 0 | U17: =MasterTables!BX22 -> 2 | AB17: =D16 -> 14 | AD17: FN | AH17: =D19 -> 57 | AJ17: EXP | GB17: 13 | GC17: G | GG17: 4 | GH17: F | GI17: G | GJ17: A | GK17: E | GL17: G | GM17: G | GN17: G | GO17: A | GP17: SA | GR17: E | GS17: 5 | GU17: 4 | GV17: X | HG17: 43835 | HH17: =TEXT(HG17,"DD-MMM") -> 05-Jan | HI17: Capricorn | HJ17: Earth | HK17: =HI17&" - "&HJ17 -> Capricorn - Earth
A18: Last Name | B18: MEENA | D18: =MasterTables!AM6 -> 20 | E18: =IF(D18<10,D18,((LEFT(D18,1))+(RIGHT(D18,1)))) -> 2 | J18: LP | L18: =C7 -> 2 | Q18: 3 | R18: =MasterTables!CF23 -> 0 | S18: =MasterTables!CG23 -> 0 | U18: =MasterTables!BX23 -> 3 | AA18: 1 | AB18: =IF(ISERROR(INDEX(GB:GB,MATCH(AB17,$GB$1:$GB$102,1)+1,1)),"",INDEX(GB:GB,MATCH(AB17,$GB$1:$GB$102,1)+1,1)) -> 15 | AC18: =MOD(AB18-1,9)+1 -> 6 | AD18: =INDEX($AH$2:$AQ$11,MATCH(AC18,$AH$2:$AQ$2,0),MATCH($AD$16,$AH$2:$AH$11,0)) -> G | AE18: =INDEX($AH$2:$AQ$11,MATCH(AC18,$AH$2:$AQ$2,0),MATCH($AE$16,$AH$2:$AH$11,0)) -> G | AG18: 1 | AH18: =IF(ISERROR(INDEX(GB:GB,MATCH(AH17,$GB$1:$GB$102,1)+1,1)),"",INDEX(GB:GB,MATCH(AH17,$GB$1:$GB$102,1)+1,1)) -> 59 | AI18: =MOD(AH18-1,9)+1 -> 5 | AJ18: =INDEX($AH$2:$AQ$11,MATCH(AI18,$AH$2:$AQ$2,0),MATCH($AJ$16,$AH$2:$AH$11,0)) -> F | AK18: =INDEX($AH$2:$AQ$11,MATCH(AI18,$AH$2:$AQ$2,0),MATCH($AK$16,$AH$2:$AH$11,0)) -> F | GB18: 14 | GC18: G | GG18: 5 | GH18: G | GI18: F | GJ18: G | GK18: G | GL18: E | GM18: F | GN18: G | GO18: VG | GP18: F | GR18: F | GS18: 8 | GU18: 5 | GV18: √ | GX18: MN Vovel | GY18: =(GZ18*GZ19)+(HA18*HA19)+(HB18*HB19)+(HC18*HC19)+(HD18*HD19) -> 0 | GZ18: =IFERROR((HLOOKUP(GZ12,C16:Z17,2,0)),0) -> 0 | HA18: =IFERROR((HLOOKUP(HA12,C16:Z17,2,0)),0) -> 0 | HB18: =IFERROR((HLOOKUP(HB12,C16:Z17,2,0)),0) -> 0 | HC18: =IFERROR((HLOOKUP(HC12,C16:Z17,2,0)),0) -> 0 | HD18: =IFERROR((HLOOKUP(HD12,C16:Z17,2,0)),0) -> 0 | HG18: 43836 | HH18: =TEXT(HG18,"DD-MMM") -> 06-Jan | HI18: Capricorn | HJ18: Earth | HK18: =HI18&" - "&HJ18 -> Capricorn - Earth
A19: Full Name | D19: =MasterTables!AM7 -> 57 | E19: =SUM(E16:E18) -> 12 | F19: =MasterTables!AO7 -> EXP | G19: =MasterTables!AP7 -> √ | J19: FN | K19: =D16 -> 14 | L19: =MOD(K19-1,9)+1 -> 5 | M19: =INDEX($AH$2:$AQ$11,MATCH(L19,$AH$2:$AQ$2,0),MATCH($L$17,$AH$2:$AH$11,0)) -> F | N19: =INDEX($AH$2:$AQ$11,MATCH(L19,$AH$2:$AQ$2,0),MATCH($L$18,$AH$2:$AH$11,0)) -> F | Q19: 4 | R19: =MasterTables!CF24 -> 0 | S19: =MasterTables!CG24 -> 0 | U19: =MasterTables!BX24 -> 2 | AA19: 2 | AB19: =IF(ISERROR(INDEX(GB:GB,MATCH(AB18,$GB$1:$GB$102,1)+1,1)),"",INDEX(GB:GB,MATCH(AB18,$GB$1:$GB$102,1)+1,1)) -> 17 | AC19: =MOD(AB19-1,9)+1 -> 8 | AD19: =INDEX($AH$2:$AQ$11,MATCH(AC19,$AH$2:$AQ$2,0),MATCH($AD$16,$AH$2:$AH$11,0)) -> A | AE19: =INDEX($AH$2:$AQ$11,MATCH(AC19,$AH$2:$AQ$2,0),MATCH($AE$16,$AH$2:$AH$11,0)) -> A | AG19: 2 | AH19: =IF(ISERROR(INDEX(GB:GB,MATCH(AH18,$GB$1:$GB$102,1)+1,1)),"",INDEX(GB:GB,MATCH(AH18,$GB$1:$GB$102,1)+1,1)) -> 60 | AI19: =MOD(AH19-1,9)+1 -> 6 | AJ19: =INDEX($AH$2:$AQ$11,MATCH(AI19,$AH$2:$AQ$2,0),MATCH($AJ$16,$AH$2:$AH$11,0)) -> G | AK19: =INDEX($AH$2:$AQ$11,MATCH(AI19,$AH$2:$AQ$2,0),MATCH($AK$16,$AH$2:$AH$11,0)) -> G | GB19: 15 | GC19: G | GG19: 6 | GH19: F | GI19: G | GJ19: A | GK19: G | GL19: F | GM19: E | GN19: G | GO19: G | GP19: G | GR19: G | GS19: 3 | GU19: 6 | GV19: √ | GZ19: =COUNTIFS(C16:Z16,GZ12) -> 0 | HA19: =COUNTIFS(C16:Z16,HA12) -> 0 | HB19: =COUNTIFS(C16:Z16,HB12) -> 0 | HC19: =COUNTIFS(C16:Z16,HC12) -> 0 | HD19: =COUNTIFS(C16:Z16,HD12) -> 0 | HG19: 43837 | HH19: =TEXT(HG19,"DD-MMM") -> 07-Jan | HI19: Capricorn | HJ19: Earth | HK19: =HI19&" - "&HJ19 -> Capricorn - Earth
J20: EXP | K20: =D19 -> 57 | L20: =MOD(K20-1,9)+1 -> 3 | M20: =INDEX($AH$2:$AQ$11,MATCH(L20,$AH$2:$AQ$2,0),MATCH($L$17,$AH$2:$AH$11,0)) -> G | N20: =INDEX($AH$2:$AQ$11,MATCH(L20,$AH$2:$AQ$2,0),MATCH($L$18,$AH$2:$AH$11,0)) -> G | Q20: 5 | R20: =MasterTables!CF25 -> 0 | S20: =MasterTables!CG25 -> 0 | U20: =MasterTables!BX25 -> 6 | AA20: 3 | AB20: =IF(ISERROR(INDEX(GB:GB,MATCH(AB19,$GB$1:$GB$102,1)+1,1)),"",INDEX(GB:GB,MATCH(AB19,$GB$1:$GB$102,1)+1,1)) -> 19 | AC20: =MOD(AB20-1,9)+1 -> 1 | AD20: =INDEX($AH$2:$AQ$11,MATCH(AC20,$AH$2:$AQ$2,0),MATCH($AD$16,$AH$2:$AH$11,0)) -> G | AE20: =INDEX($AH$2:$AQ$11,MATCH(AC20,$AH$2:$AQ$2,0),MATCH($AE$16,$AH$2:$AH$11,0)) -> G | AG20: 3 | AH20: =IF(ISERROR(INDEX(GB:GB,MATCH(AH19,$GB$1:$GB$102,1)+1,1)),"",INDEX(GB:GB,MATCH(AH19,$GB$1:$GB$102,1)+1,1)) -> 64 | AI20: =MOD(AH20-1,9)+1 -> 1 | AJ20: =INDEX($AH$2:$AQ$11,MATCH(AI20,$AH$2:$AQ$2,0),MATCH($AJ$16,$AH$2:$AH$11,0)) -> G | AK20: =INDEX($AH$2:$AQ$11,MATCH(AI20,$AH$2:$AQ$2,0),MATCH($AK$16,$AH$2:$AH$11,0)) -> G | GB20: 17 | GC20: G | GG20: 7 | GH20: G | GI20: VG | GJ20: G | GK20: G | GL20: G | GM20: G | GN20: E | GO20: A | GP20: A | GR20: H | GS20: 5 | GU20: 7 | GV20: X | HG20: 43838 | HH20: =TEXT(HG20,"DD-MMM") -> 08-Jan | HI20: Capricorn | HJ20: Earth | HK20: =HI20&" - "&HJ20 -> Capricorn - Earth
